Workbook

Sheet Assumptions
A1: AirLine and Vistara-
A2: base revenue scaled to INR 100,000 Cr for FY24, while actual combined FY24 revenues for Air India and Vistara were around INR 51,365 Cr for Air India Group and INR 15,191 Cr for Vistara, implying this is a hypothetical or forward-looking normalized view to simplify analysis)
A3: Metric | B3: Value | C3: Notes
A4: Currency | B4: INR Cr | C4: All figures normalized
A5: Base Year | B5: FY24 | C5: Post-normalization
B6: 100000
A7: Revenue growth | B7: 0.1 | C7: (10% growth assumption, compounded annually).
A8: Other Opex | B8: 0.05 | C8: growing ~5% YoY, lower than revenue to improve margins).
A9: Lease Rentals | B9: 0.04 | C9: (fixed escalation).
A10: Fuel Cost % of Revenue | B10: 0.35 | C10: -Revenue * Assumptions!B4 (but slightly adjusted downward to ~34% in later years, perhaps for efficiency gains).
A11: Target EBITDAR Margin % | B11: 22 | C11: Mature airline
A13: Synergy captured | B13: FY25 | C13: 0.2 | D13: Assumed total potential synergies * Capture % (total potential seems ~10,000 Cr based on ramp-up; not explicitly stated but implied as capture % increases).
B14: FY26 | C14: 0.5 | D14: Ramp-up: Starts low (20% in year 1) due to integration challenges, nearing full (85%) by FY28.
B15: FY27 | C15: 0.8
B16: FY28 | C16: 0.85
A18: Mergers save money—e.g., fewer duplicate staff, better fuel deals. Here, savings start at 2,000 Cr in FY25 and grow to 8,500 Cr by FY28 as the companies fully integrate. This is conservative; real mergers like Air India-Vistara (completed Nov 2024) targeted similar operational efficiencies.
A19: Multiples: Increase over time (6x to 7.5x), assuming improved market perception post-merger.
B20: FY25 | C20: 6 | D20: integration phase
B21: FY26 | C21: 6.5
B22: FY27 | C22: 7
B23: FY28 | C23: 7.5 | D23: stable, scaled airline
A24: Net Debt: Decreases ~7-10% YoY (paydown from cash flows).
A25: In crores | B25: FY | C25: 45000 | D25: (This is likely the combined net debt of Air India + Vistara at the time of merger, adjusted/normalized for the model.)
A27: The model assumes the company repays around 3,000–4,000 Cr of net debt per year.
B28: FY25 | C28: 0
A29: In crores | B29: FY26 | C29: 3000
B30: FY27 | C30: 4000
B31: FY28 | C31: 4000
A33: The original uses multiples, which are market-based but volatile. DCF estimates intrinsic value by projecting free cash flows (FCF) and discounting them
A34: Depreciation: | C34: 0.05 | E34: of revenue (for owned assets).
A35: Capex | C35: 0.06 | E35: of revenue (maintenance + growth).
A36: Change in Working Capital (ΔWC): | C36: 0.03 | E36: of revenue growth (inventory/fuel prepays).
A37: Tax Rate | C37: 0.25
A38: Tax Rate | C38: 0.1 | E38: (cost of capital; airlines ~8-12% due to risk).
A39: Terminal Growth | C39: 0.04 | E39: (mature industry
A41: Method Used: EV / EBITDAR
A43: This is industry-standard for airlines because:
A44: Neutralizes lease vs owned aircraft
A45: Avoids distorted depreciation & interest
A46: Comparable across carriers
...

Sheet Normalized_IS
B1: FY24 | C1: FY25 | D1: FY26 | E1: FY27 | F1: FY28
A2: Revenue | B2: 100000 | C2: =B2*(1+Assumptions!$B$7) -> 110000 | D2: =C2*(1+Assumptions!$B$7) -> 121000 | E2: =D2*(1+Assumptions!$B$7) -> 133100 | F2: =E2*(1+Assumptions!$B$7) -> 146410
A3: Fuel Cost | B3: =-B2*Assumptions!$B$10 -> -35000 | C3: =-C2*0.34 -> -37400 | D3: =-D2*0.34 -> -41140 | E3: =-E2*0.34 -> -45254 | F3: =-F2*0.34 -> -49779.4
A4: Other Opex | B4: -43000 | C4: =B4*(1+Assumptions!$B$8) -> -45150 | D4: =C4*(1+Assumptions!$B$8) -> -47407.5 | E4: =D4*(1+Assumptions!$B$8) -> -49777.875 | F4: =E4*(1+Assumptions!$B$8) -> -52266.769
A5: EBITDAR | B5: =B2+B3+B4 -> 22000 | C5: =C2+C3+C4 -> 27450 | D5: =D2+D3+D4 -> 32452.5 | E5: =E2+E3+E4 -> 38068.125 | F5: =F2+F3+F4 -> 44363.831
A6: Lease Rentals | B6: -12000 | C6: =B6*(1+Assumptions!$B$9) -> -12480 | D6: =C6*(1+Assumptions!$B$9) -> -12979.2 | E6: =D6*(1+Assumptions!$B$9) -> -13498.368 | F6: =E6*(1+Assumptions!$B$9) -> -14038.303
A7: EBITDA | B7: =B5+B6 -> 10000 | C7: =C5+C6 -> 14970 | D7: =D5+D6 -> 19473.3 | E7: =E5+E6 -> 24569.757 | F7: =F5+F6 -> 30325.529
A8: Chane in WC | C8: =C2-B2 -> 10000 | D8: =D2-C2 -> 11000 | E8: =E2-D2 -> 12100 | F8: =F2-E2 -> 13310

Sheet Synergies
A1: Year | B1: Synergy Capture % | C1: Cost Synergy Value | D1: 10000
A2: FY25 | B2: =Assumptions!C13 -> 0.2 | C2: =B2*$D$1 -> 2000
A3: FY26 | B3: =Assumptions!C14 -> 0.5 | C3: =B3*$D$1 -> 5000
A4: FY27 | B4: =Assumptions!C15 -> 0.8 | C4: =B4*$D$1 -> 8000
A5: FY28 | B5: =Assumptions!C16 -> 0.85 | C5: =B5*$D$1 -> 8500
B7: Captures cost savings from the merger (e.g., combined operations, route optimization, bulk purchasing).

Sheet Accretion_EBITDAR
B1: Compares standalone (pre-merger) vs. merged EBITDAR to show value creation
A2: Year | B2: Standalone EBITDAR | C2: Merged EBITDAR | D2: Accretion | E2: Accretion (e.g., FY25): = Merged EBITDAR - Standalone EBITDAR.
A3: FY25 | B3: 25000 | C3: =Normalized_IS!C5 -> 27450 | D3: =C3-B3 -> 2450
A4: FY26 | B4: 28000 | C4: =Normalized_IS!D5 -> 32452.5 | D4: =C4-B4 -> 4452.5
A5: FY27 | B5: 32000 | C5: =Normalized_IS!E5 -> 38068.125 | D5: =C5-B5 -> 6068.125
A6: FY28 | B6: 36000 | C6: =Normalized_IS!F5 -> 44363.831 | D6: =C6-B6 -> 8363.8313
B7: Standalone
B8: Assumed lower growth/margins without merger (e.g., ~10-14% YoY growth from implied FY24 base).
B9: Accretion" means the merger boosts earnings. Without it, EBITDAR would be lower (e.g., 25,000 Cr in FY25). With merger synergies, it's 27,450 Cr—adding 2,450 Cr value. This grows over time as synergies ramp up. Note: Accretion slightly exceeds synergies (e.g., 2,450 vs. 2,000 in FY25), suggesting extra benefits like revenue uplift.

Sheet Valuation_EBITDAR
A1: Values the merged entity using EV/EBITDAR multiples (common for airlines due to high leases).
A2: Metric | B2: FY25 | C2: FY26 | D2: FY27 | E2: FY28
A3: EBITDAR (Merged) | B3: =Normalized_IS!C5 -> 27450 | C3: =Normalized_IS!D5 -> 32452.5 | D3: =Normalized_IS!E5 -> 38068.125 | E3: =Normalized_IS!F5 -> 44363.831
A4: Selected EV/EBITDAR Multiple | B4: =Assumptions!C20 -> 6 | C4: =Assumptions!C21 -> 6.5 | D4: =Assumptions!C22 -> 7 | E4: =Assumptions!C23 -> 7.5
A5: Enterprise Value (INR Cr) | B5: =B3*B4 -> 164700 | C5: =C3*C4 -> 210941.25 | D5: =D3*D4 -> 266476.88 | E5: =E3*E4 -> 332728.73
A6: Net Debt (Assumed) | B6: =Assumptions!C25 -> 45000 | C6: =B6-Assumptions!C29 -> 42000 | D6: =C6-Assumptions!C30 -> 38000 | E6: =D6-Assumptions!C31 -> 34000
A7: Equity Value | B7: =B5-B6 -> 119700 | C7: =C5-C6 -> 168941.25 | D7: =D5-D6 -> 228476.88 | E7: =E5-E6 -> 298728.73
A9: Enterprise Value (e.g., FY25): = EBITDAR * Multiple (27,450 * 6 = 164,700).
A10: Equity Value: = EV - Net Debt.
A12: EV is the total value of the business (equity + debt). We multiply EBITDAR by a multiple (like P/E but for airlines). Multiples rise as the company matures. Subtract debt for equity value. This projects growth from ~120k Cr equity in FY25 to ~300k Cr by FY28—optimistic but based on synergies. Real multiples for airlines average ~7-9x EV/EBITDAR (or 7-12x EV/EBITDA, since EBITDAR includes rent). The model's 6-7.5x is conservative compared to peers like American Airlines (8-12x EV/EBITDA). Actual post-merger valuation was ~INR 36,000-56,000 Cr equity in late 2024, so this model likely projects future upside.

Sheet DCF
A1: Year | B1: Revenue | C1: EBITDA | D1: Dep | E1: EBIT | F1: NOPAT | G1: Capex | H1: ΔWC | I1: FCF
A2: FY25 | B2: =Normalized_IS!C2 -> 110000 | C2: =Normalized_IS!C7 -> 14970 | D2: =B2*Assumptions!$C$34 -> 5500 | E2: =C2-D2 -> 9470 | F2: =E2*(1-Assumptions!$C$37) -> 7102.5 | G2: =B2*Assumptions!$C$35 -> 6600 | H2: =Normalized_IS!C8*Assumptions!$C$36 -> 300 | I2: =F2+D2-G2-H2 -> 5702.5
A3: FY26 | B3: =Normalized_IS!D2 -> 121000 | C3: =Normalized_IS!D7 -> 19473.3 | D3: =B3*Assumptions!$C$34 -> 6050 | E3: =C3-D3 -> 13423.3 | F3: =E3*(1-Assumptions!$C$37) -> 10067.475 | G3: =B3*Assumptions!$C$35 -> 7260 | H3: =Normalized_IS!D8*Assumptions!$C$36 -> 330 | I3: =F3+D3-G3-H3 -> 8527.475
A4: FY27 | B4: =Normalized_IS!E2 -> 133100 | C4: =Normalized_IS!E7 -> 24569.757 | D4: =B4*Assumptions!$C$34 -> 6655 | E4: =C4-D4 -> 17914.757 | F4: =E4*(1-Assumptions!$C$37) -> 13436.068 | G4: =B4*Assumptions!$C$35 -> 7986 | H4: =Normalized_IS!E8*Assumptions!$C$36 -> 363 | I4: =F4+D4-G4-H4 -> 11742.068
A5: FY28 | B5: =Normalized_IS!F2 -> 146410 | C5: =Normalized_IS!F7 -> 30325.529 | D5: =B5*Assumptions!$C$34 -> 7320.5 | E5: =C5-D5 -> 23005.029 | F5: =E5*(1-Assumptions!$C$37) -> 17253.771 | G5: =B5*Assumptions!$C$35 -> 8784.6 | H5: =Normalized_IS!F8*Assumptions!$C$36 -> 399.3 | I5: =F5+D5-G5-H5 -> 15390.371
A7: EBIT = EBITDA - Depreciation.
A8: NOPAT = EBIT * (1 - Tax).
A9: FCF = NOPAT + Depreciation - Capex - ΔWC.
A10: Terminal Value (after FY28) = FY28 FCF * (1 + Growth) / (WACC - Growth).
A11: EV = PV of FCFs (FY25-28) + PV of Terminal Value.
D13: FY25 | E13: FY26 | F13: FY27 | G13: FY28
B14: PV of FCF | D14: =I2 -> 5702.5 | E14: =I3 -> 8527.475 | F14: =I4 -> 11742.068 | G14: =I5 -> 15390.371
D15: =D14/(1+Assumptions!C38)^1 -> 5184.0909 | E15: =E14/(1+Assumptions!$C$38)^2 -> 7047.5 | F15: =F14/(1+Assumptions!$C$38)^3 -> 8821.9893 | G15: =G14/(1+Assumptions!$C$38)^4 -> 10511.831
B16: Terminal value | G16: =DCF!I5*(1+Assumptions!C39)/(Assumptions!C38-Assumptions!C39) -> 266766.44
G17: =G16/(1.1)^4 -> 182205.07
G18: =D15+E15+F15+G15 -> 31565.411
G19: =G17+G18 -> 213770.48
B20: Total EV
D21: Bull | E21: Base | F21: Bear
A22: Fixed Inputs from Model (FY28): | D22: 0.33 | E22: 0.35 | F22: 0.37
A23: Revenue | C23: 146410 | D23: =-C23*D22 -> -48315.3 | E23: =-C23*E22 -> -51243.5 | F23: =-C23*F22 -> -54171.7 | I23: Fuel Cost = - (Revenue × Fuel %)
A24: Other Opex | C24: -52266.769 | D24: =C24 -> -52266.769 | E24: =D24 -> -52266.769 | F24: =E24 -> -52266.769 | I24: EBITDAR = Revenue + Fuel Cost + Other Opex (= Revenue - |Fuel Cost| - |Other Opex|)
A25: Base EBITDAR | C25: =Normalized_IS!F5 -> 44363.831 | D25: =$C$23+D23+$D$24 -> 45827.931 | E25: =$C$23+E23+$D$24 -> 42899.731 | F25: =$C$23+F23+$D$24 -> 39971.531 | I25: Impact per 1% fuel change: ~1,464 Cr swing in EBITDAR (since 1% of 146,410 revenue).
A28: Fuel % \ Multiple | C28: 6 | D28: 6.5 | E28: 7 | F28: 7.5
B29: 33% (Bull) | C29: =D25*$C$28 -> 274967.59 | D29: =D25*$D$28 -> 297881.55 | E29: =D25*$E$28 -> 320795.52 | F29: =D25*F28 -> 343709.48
B30: 35% (Base) | C30: =E25*$C$28 -> 257398.39 | D30: =E25*$D$28 -> 278848.25 | E30: =E25*$E$28 -> 300298.12 | F30: =E25*F28 -> 321747.98
B31: 37% (Bear) | C31: =F25*$C$28 -> 239829.19 | D31: =F25*$D$28 -> 259814.95 | E31: =F25*E28 -> 279800.72 | F31: =F25*F28 -> 299786.48
B33: Calculate Enterprise Value (EV) for each combination: EV = EBITDAR × Multiple (Rounded to nearest whole number for table)
B34: Interpret directions:
B36: Bull (33%): Higher EBITDAR → ↑ EV vs. Base
B37: Bear (37%): Lower EBITDAR → ↓ EV vs. Base

Sheet Sheet2
A2: Multiple \ Fuel % | B2: 33% (Bull) | C2: 35% (Base) | D2: 37% (Bear)
A3: 6.0x | B3: 274974 | C3: 257400 | D3: 239832
A4: 6.5x | B4: 297888 | C4: 278850 | D4: 259818
A5: 7.0x | B5: 320803 | C5: 300300 | D5: 279804
A6: 7.5x | B6: 343718 | C6: 321750 | D6: 299790
A7: Bull (low fuel) gives ~6-7% higher EV.
A8: Bear (high fuel) gives ~6-7% lower EV.
A9: Higher multiples make the good/bad scenarios swing more in absolute terms.
A11: Metric | B11: Enterprise Value (INR Cr)
A12: Mean (Expected) | B12: 300346
A13: Median | B13: 300357
A14: 10th Percentile (Downside risk) | B14: 274041
A15: 90th Percentile (Upside potential) | B15: 326792
A46: EV Range (INR Cr) | B46: Number of Simulations
A47: 249,060 – 254,184 | B47: 123
A48: 254,184 – 259,309 | B48: 114
A49: 259,309 – 264,433 | B49: 156
A50: 264,433 – 269,557 | B50: 283
A51: 269,557 – 274,682 | B51: 384
A52: 274,682 – 279,806 | B52: 533
A53: 279,806 – 284,930 | B53: 644
A54: 284,930 – 290,055 | B54: 826
A55: 290,055 – 295,179 | B55: 937
A56: 295,179 – 300,304 | B56: 992
A57: 300,304 – 305,428 | B57: 1000
A58: 305,428 – 310,552 | B58: 914
... A66: 346,423 – 351,547 | B66: 112
