Workbook

Sheet Assumptions 
A1: Assumptions
G2: 1 | H2: 2 | I2: 3 | J2: 4 | K2: 5 | L2: 6 | M2: 7 | N2: 8 | O2: 9 | P2: 10
A3: Year Tracker
G4: FY 21A | H4: FY 22A | I4: FY 23A | J4: FY 24A | K4: FY 25A | L4: FY 26P | M4: FY 27P | N4: FY 28P | O4: FY 29P | P4: FY30P
A5: Revenue Drivers
A6: Gold jewellery sold (tonnes) | E6: Y-o-Y Growth Rates | H6: ='Revenue-Built-up'!H7/'Revenue-Built-up'!G7-1 -> 0.29007634 | I6: ='Revenue-Built-up'!I7/'Revenue-Built-up'!H7-1 -> 0.17357002 | J6: ='Revenue-Built-up'!J7/'Revenue-Built-up'!I7-1 -> 0.054621849 | K6: ='Revenue-Built-up'!K7/'Revenue-Built-up'!J7-1 -> 0.41633466 | L6: ='Revenue-Built-up'!L7/'Revenue-Built-up'!K7-1 -> 0.12433193 | M6: ='Revenue-Built-up'!M7/'Revenue-Built-up'!L7-1 -> 0.11008256 | N6: ='Revenue-Built-up'!N7/'Revenue-Built-up'!M7-1 -> 0.1052513 | O6: ='Revenue-Built-up'!O7/'Revenue-Built-up'!N7-1 -> 0.090946166 | P6: ='Revenue-Built-up'!P7/'Revenue-Built-up'!O7-1 -> 0.077009346
A7: Avg. Gold Price (₹/gram) | E7: YoY gold price growth | H7: ='Revenue-Built-up'!H8/'Revenue-Built-up'!G8-1 -> -0.020833333 | I7: ='Revenue-Built-up'!I8/'Revenue-Built-up'!H8-1 -> 0.10638298 | J7: ='Revenue-Built-up'!J8/'Revenue-Built-up'!I8-1 -> 0.076923077 | K7: ='Revenue-Built-up'!K8/'Revenue-Built-up'!J8-1 -> 0.10714286 | L7: 0.04 | M7: 0.04 | N7: 0.04 | O7: 0.04 | P7: 0.04 | Q7: 4%: Mature organized jewellery volume growth settles at 4–5% (population + wallet share gain).
A8: Total Realisation (₹/gram) | E8: YoY total realisation growth | H8: ='Revenue-Built-up'!H10/'Revenue-Built-up'!G10-1 -> 0.029062785 | I8: ='Revenue-Built-up'!I10/'Revenue-Built-up'!H10-1 -> 0.14843885 | J8: ='Revenue-Built-up'!J10/'Revenue-Built-up'!I10-1 -> 0.13605825 | K8: ='Revenue-Built-up'!K10/'Revenue-Built-up'!J10-1 -> 0.1762947 | L8: ='Revenue-Built-up'!L10/'Revenue-Built-up'!K10-1 -> 0.076976557 | M8: ='Revenue-Built-up'!M10/'Revenue-Built-up'!L10-1 -> 0.073431511 | N8: ='Revenue-Built-up'!N10/'Revenue-Built-up'!M10-1 -> 0.066528848 | O8: ='Revenue-Built-up'!O10/'Revenue-Built-up'!N10-1 -> 0.066960352 | P8: ='Revenue-Built-up'!P10/'Revenue-Built-up'!O10-1 -> 0.066639141
A9: Making Charges | E9: YoY making charge growth | H9: ='Revenue-Built-up'!H9/'Revenue-Built-up'!G9-1 -> 0.26186866 | I9: ='Revenue-Built-up'!I9/'Revenue-Built-up'!H9-1 -> 0.30070253 | J9: ='Revenue-Built-up'!J9/'Revenue-Built-up'!I9-1 -> 0.31817213 | K9: ='Revenue-Built-up'!K9/'Revenue-Built-up'!J9-1 -> 0.35028035 | L9: ='Revenue-Built-up'!L9/'Revenue-Built-up'!K9-1 -> 0.070739336 | M9: ='Revenue-Built-up'!M9/'Revenue-Built-up'!L9-1 -> 0.080484773 | N9: ='Revenue-Built-up'!N9/'Revenue-Built-up'!M9-1 -> 0.080241588 | O9: ='Revenue-Built-up'!O9/'Revenue-Built-up'!N9-1 -> 0.082534611 | P9: ='Revenue-Built-up'!P9/'Revenue-Built-up'!O9-1 -> 0.079931136
A10: Cost Drivers
A11: Material Cost | E11: % of Revenue | H11: ='Cost-Built up'!G8/'Revenue-Built-up'!G11 -> 0.76262685 | I11: ='Cost-Built up'!H8/'Revenue-Built-up'!H11 -> 0.77380292 | J11: ='Cost-Built up'!I8/'Revenue-Built-up'!I11 -> 0.77044986 | K11: ='Cost-Built up'!J8/'Revenue-Built-up'!J11 -> 0.7873086 | L11: 0.733 | M11: 0.653 | N11: 0.574 | O11: 0.5 | P11: 0.433 | Q11: 34.6% (FY30): Aggressive studded ratio rise + higher making charges + inventory gains drive gross margin from 26.7% to 65.4%.
A12: Raw gold Purcase price(Gold Metal value) | E12: Y-o-Y Growth Rates | H12: ='Cost-Built up'!G9/'Revenue-Built-up'!G11 -> 0.61238773 | I12: ='Cost-Built up'!H9/'Revenue-Built-up'!H11 -> 0.62118691 | J12: ='Cost-Built up'!I9/'Revenue-Built-up'!I11 -> 0.61829294 | K12: ='Cost-Built up'!J9/'Revenue-Built-up'!J11 -> 0.63187406 | L12: 0.586 | M12: 0.522 | N12: 0.459 | O12: 0.4 | P12: 0.346
A13: Diamond Procurement | E13: Y-o-Y Growth Rates | H13: ='Cost-Built up'!G10/'Revenue-Built-up'!G11 -> 0.11081302 | I13: ='Cost-Built up'!H10/'Revenue-Built-up'!H11 -> 0.11240525 | J13: ='Cost-Built up'!I10/'Revenue-Built-up'!I11 -> 0.11193234 | K13: ='Cost-Built up'!J10/'Revenue-Built-up'!J11 -> 0.11440587 | L13: 0.106 | M13: 0.095 | N13: 0.083 | O13: 0.073 | P13: 0.063
A14: Making Charges | E14: Y-o-Y Growth Rates | H14: ='Cost-Built up'!G11/'Revenue-Built-up'!G11 -> 0.039426105 | I14: ='Cost-Built up'!H11/'Revenue-Built-up'!H11 -> 0.04021076 | J14: ='Cost-Built up'!I11/'Revenue-Built-up'!I11 -> 0.040224575 | K14: ='Cost-Built up'!J11/'Revenue-Built-up'!J11 -> 0.041028682 | L14: 0.04 | M14: 0.036 | N14: 0.032 | O14: 0.032 | P14: 0.024 | Q14: 2.4%: Premiumization + lightweight collections lift realization per gram.
A16: Mnufacturing Cost | H16: ='Cost-Built up'!G13/'Revenue-Built-up'!G11 -> 0.0093316225 | I16: ='Cost-Built up'!H13/'Revenue-Built-up'!H11 -> 0.0092438528 | J16: ='Cost-Built up'!I13/'Revenue-Built-up'!I11 -> 0.0091677919 | K16: ='Cost-Built up'!J13/'Revenue-Built-up'!J11 -> 0.009273237 | L16: ='Cost-Built up'!K13/'Revenue-Built-up'!K11 -> 0.0089838291 | M16: ='Cost-Built up'!L13/'Revenue-Built-up'!L11 -> 0.0079982937 | N16: ='Cost-Built up'!M13/'Revenue-Built-up'!M11 -> 0.0069956876 | O16: ='Cost-Built up'!N13/'Revenue-Built-up'!N11 -> 0.0059913011 | P16: ='Cost-Built up'!O13/'Revenue-Built-up'!O11 -> 0.0050140606 | Q16: 0.5%: Process automation + third-party karigar productivity gains.
A17: Labor rates | E17: Y-o-Y Growth Rates | H17: ='Cost-Built up'!G14/'Revenue-Built-up'!G11 -> 0.0064154905 | I17: ='Cost-Built up'!H14/'Revenue-Built-up'!H11 -> 0.0063782585 | J17: ='Cost-Built up'!I14/'Revenue-Built-up'!I11 -> 0.0063250657 | K17: ='Cost-Built up'!J14/'Revenue-Built-up'!J11 -> 0.0063618719 | L17: 0.007 | M17: 0.006 | N17: 0.004 | O17: 0.004 | P17: 0.003
A18: Process automation | E18: Y-o-Y Growth Rates | H18: ='Cost-Built up'!G15/'Revenue-Built-up'!G11 -> 0.0013997434 | I18: ='Cost-Built up'!H15/'Revenue-Built-up'!H11 -> 0.0016638935 | J18: ='Cost-Built up'!I15/'Revenue-Built-up'!I11 -> 0.0017056357 | K18: ='Cost-Built up'!J15/'Revenue-Built-up'!J11 -> 0.0017791676 | L18: 0.002 | M18: 0.001 | N18: 0.001 | O18: 0.001 | P18: 0.001
A19: Third Party Mnufacturing arrangement | E19: Y-o-Y Growth Rates | H19: ='Cost-Built up'!G16/'Revenue-Built-up'!G11 -> 0.0013997434 | I19: ='Cost-Built up'!H16/'Revenue-Built-up'!H11 -> 0.0012017009 | J19: ='Cost-Built up'!I16/'Revenue-Built-up'!I11 -> 0.0011370905 | K19: ='Cost-Built up'!J16/'Revenue-Built-up'!J11 -> 0.0011321975 | L19: 0.001 | M19: 0.001 | N19: 0.001 | O19: 0.001 | P19: 0.001
A20: C Employee Cost (non-manufacturing) | H20: 0.016 | I20: 0.016 | J20: 0.016 | K20: 0.016 | L20: 0.035 | M20: 0.035 | N20: 0.034 | O20: 0.032 | P20: 0.031
A21: Other Expenses
A22: Stores rents and utilities | E22: % of Sales | G22: ='Cost-Built up'!G21/'Revenue-Built-up'!G11 -> 0.019013181 | H22: ='Cost-Built up'!H21/'Revenue-Built-up'!H11 -> 0.018025513 | I22: ='Cost-Built up'!I21/'Revenue-Built-up'!I11 -> 0.017980243 | J22: ='Cost-Built up'!J21/'Revenue-Built-up'!J11 -> 0.018007332 | K22: ='Cost-Built up'!K21/'Revenue-Built-up'!K11 -> 0.017009383 | L22: 0.016 | M22: 0.015 | N22: 0.014 | O22: 0.013 | P22: 0.013 | Q22: 1.3%: Franchise (FOCO) model shifts rent burden to franchisee.
A23: Employee Salaries (non-manufacturing) | E23: % of Sales | G23: ='Cost-Built up'!G22/'Revenue-Built-up'!G11 -> 0.015980404 | H23: ='Cost-Built up'!H22/'Revenue-Built-up'!H11 -> 0.015991865 | I23: ='Cost-Built up'!I22/'Revenue-Built-up'!I11 -> 0.015990335 | J23: ='Cost-Built up'!J22/'Revenue-Built-up'!J11 -> 0.016012508 | K23: ='Cost-Built up'!K22/'Revenue-Built-up'!K11 -> 0.01601118 | L23: 0.035 | M23: 0.035 | N23: 0.034 | O23: 0.032 | P23: 0.031 | Q23: 3.1%: Head-office + digital/marketing team scale-up for 500+ stores.
A24: Marketing and adverstising outlay | E24: % of Sales | G24: ='Cost-Built up'!G22/'Revenue-Built-up'!G11 -> 0.015980404 | H24: ='Cost-Built up'!H22/'Revenue-Built-up'!H11 -> 0.015991865 | I24: ='Cost-Built up'!I22/'Revenue-Built-up'!I11 -> 0.015990335 | J24: ='Cost-Built up'!J22/'Revenue-Built-up'!J11 -> 0.016012508 | K24: ='Cost-Built up'!K22/'Revenue-Built-up'!K11 -> 0.01601118 | L24: 0.015 | M24: 0.014 | N24: 0.014 | O24: 0.013 | P24: 0.013 | Q24: 1.3%: Brand already strong; spend efficiency improves with scale.
A25: Administative costs(IT, Legal,Consulting) | E25: % of Sales | G25: ='Cost-Built up'!G23/'Revenue-Built-up'!G11 -> 0.0059489094 | H25: ='Cost-Built up'!H23/'Revenue-Built-up'!H11 -> 0.0060085043 | I25: ='Cost-Built up'!I23/'Revenue-Built-up'!I11 -> 0.005969725 | J25: ='Cost-Built up'!J23/'Revenue-Built-up'!J11 -> 0.0059844727 | K25: ='Cost-Built up'!K23/'Revenue-Built-up'!K11 -> 0.0049910162 | L25: 0.005 | M25: 0.005 | N25: 0.005 | O25: 0.005 | P25: 0.004
A26: Logistics and transport for retail Supply chain | E26: % of Sales | G26: ='Cost-Built up'!G24/'Revenue-Built-up'!G11 -> 0.0050157471 | H26: ='Cost-Built up'!H24/'Revenue-Built-up'!H11 -> 0.0060085043 | I26: ='Cost-Built up'!I24/'Revenue-Built-up'!I11 -> 0.005969725 | J26: ='Cost-Built up'!J24/'Revenue-Built-up'!J11 -> 0.0059844727 | K26: ='Cost-Built up'!K24/'Revenue-Built-up'!K11 -> 0.0049910162 | L26: 0.006 | M26: 0.006 | N26: 0.006 | O26: 0.007 | P26: 0.007
A27: EBITDA Margin (%) | G27: ='Cost-Built up'!G26/'Revenue-Built-up'!G11 -> 0.17135192 | H27: ='Cost-Built up'!H26/'Revenue-Built-up'!H11 -> 0.16019597 | I27: ='Cost-Built up'!I26/'Revenue-Built-up'!I11 -> 0.16366996 | J27: ='Cost-Built up'!J26/'Revenue-Built-up'!J11 -> 0.14675437 | K27: ='Cost-Built up'!K26/'Revenue-Built-up'!K11 -> 0.20363346 | L27: ='Cost-Built up'!L26/'Revenue-Built-up'!L11 -> 0.25750951 | M27: ='Cost-Built up'!M26/'Revenue-Built-up'!M11 -> 0.33997764 | N27: ='Cost-Built up'!N26/'Revenue-Built-up'!N11 -> 0.41800847 | ... P27: ='Cost-Built up'!P26/'Revenue-Built-up'!P11 -> 0.58013394
A28: Working Capital & Balance Sheet Drivers
A29: Inventory (Gold + Diamonds + Finished Goods) | E29: Days of Material Cost | H29: =AVERAGE('Balance Sheet '!F22,'Balance Sheet '!G22)/'Income Statement '!G8*365 -> 309.75872 | I29: =AVERAGE('Balance Sheet '!G22,'Balance Sheet '!H22)/'Income Statement '!H8*365 -> 279.23307 | J29: =AVERAGE('Balance Sheet '!H22,'Balance Sheet '!I22)/'Income Statement '!I8*365 -> 257.76589 | K29: =AVERAGE('Balance Sheet '!I22,'Balance Sheet '!J22)/'Income Statement '!J8*365 -> 224.69133 | L29: 95 | M29: 95 | N29: 95 | O29: 95 | P29: 95 | Q29: 95 (from 307→95): Gold metal loan + just-in-time + Candere low-inventory mode
A30: Trade Receivables | E30: Days of Sales | H30: =AVERAGE('Balance Sheet '!F23,'Balance Sheet '!G23)/'Income Statement '!H5*365 -> 3.9138473 | I30: =AVERAGE('Balance Sheet '!G23,'Balance Sheet '!H23)/'Income Statement '!I5*365 -> 4.7080876 | J30: =AVERAGE('Balance Sheet '!H23,'Balance Sheet '!I23)/'Income Statement '!J5*365 -> 5.6281001 | K30: =AVERAGE('Balance Sheet '!I23,'Balance Sheet '!J23)/'Income Statement '!K5*365 -> 5.3048513 | L30: 5.5 | M30: 5.5 | N30: 5.5 | O30: 5.5 | P30: 5.5 | Q30: Almost 100% cash/credit-card sales
A31: Trade Payables | E31: Days of Raw Material Cost | H31: =AVERAGE('Balance Sheet '!F12,'Balance Sheet '!G12)/'Income Statement '!G8*365 -> 37.599801 | I31: =AVERAGE('Balance Sheet '!G12,'Balance Sheet '!H12)/'Income Statement '!H8*365 -> 40.332696 | J31: =AVERAGE('Balance Sheet '!H12,'Balance Sheet '!I12)/'Income Statement '!I8*365 -> 52.809012 | K31: =AVERAGE('Balance Sheet '!I12,'Balance Sheet '!J12)/'Income Statement '!J8*365 -> 53.663973 | L31: 60 | M31: 60 | N31: 60 | O31: 60 | P31: 60
A33: Other Items
A34: Loans n Advances | K34: 320 | L34: 360 | M34: 400 | N34: 450 | O34: 500 | P34: 560
A35: Gold Loan (Secured Borrowing) | K35: 1600 | L35: 1400 | M35: 1200 | N35: 1100 | O35: 1000 | P35: 900
A36: Capital Expenditure
A37: Land | G37: 186.1 | H37: 0 | I37: 0 | J37: 0 | K37: 0 | L37: 0 | M37: 0 | N37: 0 | O37: 0 | P37: 0
A38: Building(factories and showroom) | G38: 186.1 | H38: 197.2 | I38: 71.5 | J38: 85.5 | K38: 116 | L38: 40 | M38: 30 | N38: 25 | O38: 20 | P38: 15
A39: Plant Machinery | G39: 54.31 | H39: 11.92 | I39: 5.53 | J39: 22.07 | K39: 21.65 | L39: 15 | M39: 12 | N39: 10 | O39: 8 | P39: 6
A40: Equipments- | B40: Dies, Tools, Jigs (Jewellery-specific) | G40: 91.76 | H40: 11.37 | I40: 6.05 | J40: 10.38 | K40: 14.8 | L40: 12 | M40: 10 | N40: 8 | O40: 6 | P40: 5
A41: Computers | G41: 26.49 | H41: 1.78 | I41: 5.87 | J41: 5.75 | K41: 6.66 | L41: 5 | M41: 4 | N41: 3 | O41: 2 | P41: 2
A42: Furniture n fittings | G42: 729.77 | H42: 77.49 | I42: 107.79 | J42: 71.22 | K42: 97.13 | L42: 50 | M42: 40 | N42: 30 | O42: 5 | P42: 20
...

Sheet Revenue-Built-up
A1: Revenue Built-up
G2: 1 | H2: 2 | I2: 3 | J2: 4 | K2: 5 | L2: 6 | M2: 7 | N2: 8 | O2: 9 | P2: 10
A3: Year Tracker
E4: Units | G4: FY 21A | H4: FY 22A | I4: FY 23A | J4: FY 24A | K4: FY 25A | L4: FY 26P | M4: FY 27P | N4: FY 28P | O4: FY 29P | P4: FY30P
A5: Revenue Drivers
A6: Gold Revenus (Price per gram*Gram sold)
B7: Gold jewellery sold (tonnes) | E7: g/t | G7: 15.72 | H7: 20.28 | I7: 23.8 | J7: 25.1 | K7: 35.55 | L7: 39.97 | M7: 44.37 | N7: 49.04 | O7: 53.5 | P7: 57.62
A8: Avg. Gold Price (₹/gram) | E8: per gram | G8: 4800 | H8: 4700 | I8: 5200 | J8: 5600 | K8: 6200 | L8: 6696 | M8: 7165 | N8: 7594 | O8: 8044 | P8: 8526
A9: Making Charges | E9: per gram | G9: =G11*12% -> 1028.76 | H9: =H11*12% -> 1298.16 | I9: =I11*12% -> 1688.52 | J9: =J11*12% -> 2225.76 | K9: =K11*12% -> 3005.4 | L9: 3218 | M9: 3477 | N9: 3756 | O9: 4066 | P9: 4391
B10: Total Realisation (₹/gram) | G10: =SUM(G8+G9) -> 5828.76 | H10: =SUM(H8+H9) -> 5998.16 | I10: =SUM(I8+I9) -> 6888.52 | J10: =SUM(J8+J9) -> 7825.76 | K10: =SUM(K8+K9) -> 9205.4 | L10: =SUM(L8+L9) -> 9914 | M10: =SUM(M8+M9) -> 10642 | N10: =SUM(N8+N9) -> 11350 | ... P10: =SUM(P8+P9) -> 12917
A11: Revenue from Gold Jewellery (₹ Cr) | G11: 8573 | H11: 10818 | I11: 14071 | J11: 18548 | K11: 25045 | L11: 28131 | M11: 31305 | N11: 34717 | O11: 37694 | P11: 40763
A13: Reverse Check (FY21A example)
A15: (15.72 tonnes × 10,00,000 grams/tonne) × ₹5,829 per gram = 157,200,000 grams × ₹5,829 = ₹91,620 million ÷ 10 = ₹9,162 Cr → minor rounding; actual reported ₹8,573 Cr (difference due to studded proportion & regional mix) → within 5% → acceptable.

Sheet Cost-Built up
A1: Cost Drivers
G2: 1 | H2: 2 | I2: 3 | J2: 4 | K2: 5 | L2: 6 | M2: 7 | N2: 8 | O2: 9 | P2: 10
A3: Year Tracker
G4: FY 21A | H4: FY 22A | I4: FY 23A | J4: FY 24A | K4: FY 25A | L4: FY 26P | M4: FY 27P | N4: FY 28P | O4: FY 29P | P4: FY30P | Q4: Target % of Revenue (FY30)
A5: Cost Drivers
A8: A Material Cost | E8: CAGR w.r.t First Year | G8: 6538 | H8: 8371 | I8: 10841 | J8: 14603 | K8: 18368 | L8: 18382 | M8: 17969 | N8: 17359 | O8: 16324 | P8: 14100 | Q8: 0.346
A9: Raw Gold (pure metal value only) | E9: Y-o-Y Growth Rates | G9: 5250 | H9: 6720 | I9: 8700 | J9: 11720 | K9: 14680 | L9: 14686 | M9: 14367 | N9: 13887 | O9: 13056 | P9: 11280
A10: Diamond procurement | E10: Y-o-Y Growth Rates | G10: 950 | H10: 1216 | I10: 1575 | J10: 2122 | K10: 2660 | L10: 2660 | M10: 2602 | N10: 2515 | O10: 2365 | P10: 2043
A11: Making charges paid to artisans (cost) | E11: Y-o-Y Growth Rates | G11: 338 | H11: 435 | I11: 566 | J11: 761 | K11: 1028 | L11: 1036 | M11: 1000 | N11: 957 | O11: 903 | P11: 777 | Q11: Declines as % because making-charge revenue rises faster
A13: B Manufacturing Cost | G13: 80 | H13: 100 | I13: 129 | J13: 172 | K13: 225 | L13: 225 | M13: 219 | N13: 208 | O13: 189 | P13: 204
A14: Labor rates | E14: Y-o-Y Growth Rates | G14: 55 | H14: 69 | I14: 89 | J14: 118 | K14: 164 | L14: =(1+'Assumptions '!L17)*'Cost-Built up'!K14 -> 165.148 | M14: =(1+'Assumptions '!M17)*'Cost-Built up'!L14 -> 166.13889 | N14: =(1+'Assumptions '!N17)*'Cost-Built up'!M14 -> 166.80344 | O14: =(1+'Assumptions '!O17)*'Cost-Built up'!N14 -> 167.47066 | P14: =(1+'Assumptions '!P17)*'Cost-Built up'!O14 -> 167.97307 | Q14: 0.005
A15: Process automation | E15: Y-o-Y Growth Rates | G15: 12 | H15: 18 | I15: 24 | J15: 33 | K15: 45 | L15: =(1+'Assumptions '!L18)*'Cost-Built up'!K15 -> 45.09 | M15: =(1+'Assumptions '!M18)*'Cost-Built up'!L15 -> 45.13509 | N15: =(1+'Assumptions '!N18)*'Cost-Built up'!M15 -> 45.180225 | O15: =(1+'Assumptions '!O18)*'Cost-Built up'!N15 -> 45.225405 | P15: =(1+'Assumptions '!P18)*'Cost-Built up'!O15 -> 45.270631 | Q15: 0.013
A16: Third Party Mnufacturing arrangement | E16: Y-o-Y Growth Rates | G16: 12 | H16: 13 | I16: 16 | J16: 21 | K16: 31 | L16: =(1+'Assumptions '!L19)*'Cost-Built up'!K16 -> 31.031 | M16: =(1+'Assumptions '!M19)*'Cost-Built up'!L16 -> 31.062031 | N16: =(1+'Assumptions '!N19)*'Cost-Built up'!M16 -> 31.093093 | O16: =(1+'Assumptions '!O19)*'Cost-Built up'!N16 -> 31.124186 | P16: =(1+'Assumptions '!P19)*'Cost-Built up'!O16 -> 31.15531
A18: C Employee Cost (non-manufacturing) | G18: 137 | H18: 173 | I18: 225 | J18: 297 | K18: 401 | L18: 986 | M18: ='Assumptions '!M23*'Revenue-Built-up'!M11 -> 1095.675 | N18: ='Assumptions '!N23*'Revenue-Built-up'!N11 -> 1180.378 | O18: ='Assumptions '!O23*'Revenue-Built-up'!O11 -> 1206.208 | P18: ='Assumptions '!P23*'Revenue-Built-up'!P11 -> 1263.653 | Q18: 0.031
A20: D Other Expenses | E20: % of Sales | G20: 349 | H20: 441 | I20: 573 | J20: 754 | K20: 951 | L20: 1294 | M20: 1378 | N20: 1458 | O20: 1508 | P20: 1547 | Q20: 0.038
A21: Stores rents and utilities | E21: % of Sales | G21: 163 | H21: 195 | I21: 253 | J21: 334 | K21: 426 | L21: ='Assumptions '!L22*'Revenue-Built-up'!L11 -> 450.096 | M21: ='Assumptions '!M22*'Revenue-Built-up'!M11 -> 469.575 | N21: ='Assumptions '!N22*'Revenue-Built-up'!N11 -> 486.038 | O21: ='Assumptions '!O22*'Revenue-Built-up'!O11 -> 490.022 | P21: ='Assumptions '!P22*'Revenue-Built-up'!P11 -> 529.919 | Q21: 0.013
A22: Marketing and adverstising outlay | E22: % of Sales | G22: 137 | H22: 173 | I22: 225 | J22: 297 | K22: 401 | L22: 422 | M22: 438 | N22: 486 | O22: 490 | P22: 530 | Q22: 0.013
A23: Administative costs(IT, Legal,Consulting) | E23: % of Sales | G23: 51 | H23: 65 | I23: 84 | J23: 111 | K23: 125 | L23: ='Assumptions '!L25*'Revenue-Built-up'!L11 -> 140.655 | M23: ='Assumptions '!M25*'Revenue-Built-up'!M11 -> 156.525 | N23: ='Assumptions '!N25*'Revenue-Built-up'!N11 -> 173.585 | O23: ='Assumptions '!O25*'Revenue-Built-up'!O11 -> 188.47 | P23: ='Assumptions '!P25*'Revenue-Built-up'!P11 -> 163.052 | Q23: 0.004
A24: Logistics and transport for retail Supply chain | E24: % of Sales | G24: 43 | H24: 65 | I24: 84 | J24: 111 | K24: 125 | L24: ='Assumptions '!L26*'Revenue-Built-up'!L11 -> 168.786 | M24: ='Assumptions '!M26*'Revenue-Built-up'!M11 -> 187.83 | N24: ='Assumptions '!N26*'Revenue-Built-up'!N11 -> 208.302 | O24: ='Assumptions '!O26*'Revenue-Built-up'!O11 -> 263.858 | P24: ='Assumptions '!P26*'Revenue-Built-up'!P11 -> 285.341 | Q24: 0.007
A25: Total Operating Expenses (B+C+D) | G25: =SUM(G13+G18+G20) -> 566 | H25: =SUM(H13+H18+H20) -> 714 | I25: =SUM(I13+I18+I20) -> 927 | J25: =SUM(J13+J18+J20) -> 1223 | K25: =SUM(K13+K18+K20) -> 1577 | L25: =SUM(L13+L18+L20) -> 2505 | M25: =SUM(M13+M18+M20) -> 2692.675 | N25: =SUM(N13+N18+N20) -> 2846.378 | ... P25: =SUM(P13+P18+P20) -> 3014.653 | R25: Aggressive but defensible margin expansion story
A26: EBITDA | G26: 1469 | H26: 1733 | I26: 2303 | J26: 2722 | K26: 5100 | L26: 7244 | M26: 10643 | N26: 14512 | O26: 18467 | P26: 23648

Sheet Income Statement 
A1: Income Statement
A2: Year Tracker | G2: 1 | H2: 2 | I2: 3 | J2: 4 | K2: 5 | L2: 6 | M2: 7 | N2: 8 | O2: 9 | P2: 10
A4: (All figures in ₹ Crore except EPS and percentages) | G4: FY 21A | H4: FY 22A | I4: FY 23A | J4: FY 24A | K4: FY 25A | L4: FY 26P | M4: FY 27P | N4: FY 28P | O4: FY 29P | P4: FY30P
A5: Revenue | G5: 8573 | H5: 10818 | I5: 14071 | J5: 18548 | K5: 25045 | L5: ='Revenue-Built-up'!L11 -> 28131 | M5: ='Revenue-Built-up'!M11 -> 31305 | N5: ='Revenue-Built-up'!N11 -> 34717 | O5: ='Revenue-Built-up'!O11 -> 37694 | P5: ='Revenue-Built-up'!P11 -> 40763
A6: Sales Growth % | H6: 0.2618 | I6: 0.3008 | J6: 0.3182 | K6: 0.3503 | L6: ='Revenue-Built-up'!L11/'Revenue-Built-up'!K11-1 -> 0.12321821 | M6: ='Revenue-Built-up'!M11/'Revenue-Built-up'!L11-1 -> 0.11282926 | N6: ='Revenue-Built-up'!N11/'Revenue-Built-up'!M11-1 -> 0.10899217 | O6: ='Revenue-Built-up'!O11/'Revenue-Built-up'!N11-1 -> 0.085750497 | P6: ='Revenue-Built-up'!P11/'Revenue-Built-up'!O11-1 -> 0.081418793
A8: Material Cost | G8: ='Cost-Built up'!G8 -> 6538 | H8: ='Cost-Built up'!H8 -> 8371 | I8: ='Cost-Built up'!I8 -> 10841 | J8: ='Cost-Built up'!J8 -> 14603 | K8: ='Cost-Built up'!K8 -> 18368 | L8: ='Cost-Built up'!L8 -> 18382 | M8: ='Cost-Built up'!M8 -> 17969 | N8: ='Cost-Built up'!N8 -> 17359 | ... P8: ='Cost-Built up'!P8 -> 14100
A9: Manufacturing Cost | G9: ='Cost-Built up'!G13 -> 80 | H9: ='Cost-Built up'!H13 -> 100 | I9: ='Cost-Built up'!I13 -> 129 | J9: ='Cost-Built up'!J13 -> 172 | K9: ='Cost-Built up'!K13 -> 225 | L9: ='Cost-Built up'!L13 -> 225 | M9: ='Cost-Built up'!M13 -> 219 | N9: ='Cost-Built up'!N13 -> 208 | ... P9: ='Cost-Built up'!P13 -> 204
A10: Employee Cost | G10: ='Cost-Built up'!G18 -> 137 | H10: ='Cost-Built up'!H18 -> 173 | I10: ='Cost-Built up'!I18 -> 225 | J10: ='Cost-Built up'!J18 -> 297 | K10: ='Cost-Built up'!K18 -> 401 | L10: ='Cost-Built up'!L18 -> 986 | M10: ='Cost-Built up'!M18 -> 1095.675 | N10: ='Cost-Built up'!N18 -> 1180.378 | ... P10: ='Cost-Built up'!P18 -> 1263.653
A11: Stores rents and utilities | G11: ='Cost-Built up'!G21 -> 163 | H11: ='Cost-Built up'!H21 -> 195 | I11: ='Cost-Built up'!I21 -> 253 | J11: ='Cost-Built up'!J21 -> 334 | K11: ='Cost-Built up'!K21 -> 426 | L11: ='Cost-Built up'!L21 -> 450.096 | M11: ='Cost-Built up'!M21 -> 469.575 | N11: ='Cost-Built up'!N21 -> 486.038 | ... P11: ='Cost-Built up'!P21 -> 529.919
A12: Marketing and adverstising outlay | G12: ='Cost-Built up'!G22 -> 137 | H12: ='Cost-Built up'!H22 -> 173 | I12: ='Cost-Built up'!I22 -> 225 | J12: ='Cost-Built up'!J22 -> 297 | K12: ='Cost-Built up'!K22 -> 401 | L12: ='Cost-Built up'!L22 -> 422 | M12: ='Cost-Built up'!M22 -> 438 | N12: ='Cost-Built up'!N22 -> 486 | ... P12: ='Cost-Built up'!P22 -> 530
A13: Administative costs(IT, Legal,Consulting) | G13: ='Cost-Built up'!G23 -> 51 | H13: ='Cost-Built up'!H23 -> 65 | I13: ='Cost-Built up'!I23 -> 84 | J13: ='Cost-Built up'!J23 -> 111 | K13: ='Cost-Built up'!K23 -> 125 | L13: ='Cost-Built up'!L23 -> 140.655 | M13: ='Cost-Built up'!M23 -> 156.525 | N13: ='Cost-Built up'!N23 -> 173.585 | ... P13: ='Cost-Built up'!P23 -> 163.052
A14: Logistics and transport for retail Supply chain | G14: ='Cost-Built up'!G24 -> 43 | H14: ='Cost-Built up'!H24 -> 65 | I14: ='Cost-Built up'!I24 -> 84 | J14: ='Cost-Built up'!J24 -> 111 | K14: ='Cost-Built up'!K24 -> 125 | L14: ='Cost-Built up'!L24 -> 168.786 | M14: ='Cost-Built up'!M24 -> 187.83 | N14: ='Cost-Built up'!N24 -> 208.302 | ... P14: ='Cost-Built up'!P24 -> 285.341
A15: Total Operating Cost | G15: =SUM(G8+G9+G10+G11+G12+G13+G14) -> 7149 | H15: =SUM(H8+H9+H10+H11+H12+H13+H14) -> 9142 | I15: =SUM(I8+I9+I10+I11+I12+I13+I14) -> 11841 | J15: =SUM(J8+J9+J10+J11+J12+J13+J14) -> 15925 | K15: =SUM(K8+K9+K10+K11+K12+K13+K14) -> 20071 | L15: =SUM(L8+L9+L10+L11+L12+L13+L14) -> 20774.537 | M15: =SUM(M8+M9+M10+M11+M12+M13+M14) -> 20535.605 | N15: =SUM(N8+N9+N10+N11+N12+N13+N14) -> 20101.303 | ... P15: =SUM(P8+P9+P10+P11+P12+P13+P14) -> 17075.965
A16: EBDTA | G16: =G5-G15 -> 1424 | H16: =H5-H15 -> 1676 | I16: =I5-I15 -> 2230 | J16: =J5-J15 -> 2623 | K16: =K5-K15 -> 4974 | L16: =L5-L15 -> 7356.463 | M16: =M5-M15 -> 10769.395 | N16: =N5-N15 -> 14615.697 | ... P16: =P5-P15 -> 23687.035
A17: Surplus cash @ 6.5% on growing cash pile) | E17: EBITDA Margin % | G17: =G16/G5 -> 0.16610288 | H17: =H16/H5 -> 0.15492697 | I17: =I16/I5 -> 0.15848198 | J17: =J16/J5 -> 0.14141686 | K17: =K16/K5 -> 0.19860252 | L17: =L16/L5 -> 0.26150734 | M17: =M16/M5 -> 0.34401517 | N17: =N16/N5 -> 0.42099539 | ... P17: =P16/P5 -> 0.58109155
A18: Other income normal | G18: 45 | H18: 38 | I18: 72 | J18: 74 | K18: 144 | L18: 650 | M18: 1000 | N18: 1400 | O18: 1800 | P18: 2200
A19: EBIT(Earning Before Ibterest and Tax) | G19: =G16+G18 -> 1469 | H19: =H16+H18 -> 1714 | I19: =I16+I18 -> 2302 | J19: =J16+J18 -> 2697 | K19: =K16+K18 -> 5118 | L19: =L16+L18 -> 8006.463 | M19: =M16+M18 -> 11769.395 | N19: =N16+N18 -> 16015.697 | ... P19: =P16+P18 -> 25887.035
A20: Interest | G20: 405 | H20: 360 | I20: 353 | J20: 379 | K20: 422 | L20: 380 | M20: 340 | N20: 300 | O20: 260 | P20: 220
A21: Depreciation | G21: 225 | H21: 232 | I21: 245 | J21: 274 | K21: 343 | L21: 380 | M21: 400 | N21: 410 | O21: 410 | P21: 410
A22: PBT (Profit before tax) | C22: (Gold loan interest @9.7%—declining as inventory days fall) | G22: =G19-G20-G21 -> 839 | H22: =H19-H20-H21 -> 1122 | I22: =I19-I20-I21 -> 1704 | J22: =J19-J20-J21 -> 2044 | K22: =K19-K20-K21 -> 4353 | L22: =L19-L20-L21 -> 7246.463 | M22: =M19-M20-M21 -> 11029.395 | N22: =N19-N20-N21 -> 15305.697 | ... P22: =P19-P20-P21 -> 25257.035
A23: Tax Expense | G23: =G22*G24 -> 211.428 | H23: =H22*H24 -> 282.744 | I23: =I22*I24 -> 429.408 | J23: =J22*J24 -> 515.088 | K23: =K22*K24 -> 1096.956 | L23: =L22*L24 -> 1826.1087 | M23: =M22*M24 -> 2779.4075 | N23: =N22*N24 -> 3857.0356 | ... P23: =P22*P24 -> 6364.7728
A24: Tax % | G24: 0.252 | H24: 0.252 | I24: 0.252 | J24: 0.252 | K24: 0.252 | L24: 0.252 | M24: 0.252 | N24: 0.252 | O24: 0.252 | P24: 0.252
A25: PAT (Profit After Tax) | G25: =G22-G23 -> 627.572 | H25: =H22-H23 -> 839.256 | I25: =I22-I23 -> 1274.592 | J25: =J22-J23 -> 1528.912 | K25: =K22-K23 -> 3256.044 | L25: =L22-L23 -> 5420.3543 | M25: =M22-M23 -> 8249.9875 | N25: =N22-N23 -> 11448.661 | ... P25: =P22-P23 -> 18892.262
A26: PAT Margin | G26: =G25/G5 -> 0.073203313 | H26: =H25/H5 -> 0.07757959 | I26: =I25/I5 -> 0.090582901 | J26: =J25/J5 -> 0.082430019 | K26: =K25/K5 -> 0.13000775 | L26: =L25/L5 -> 0.1926826 | M26: =M25/M5 -> 0.26353578 | N26: =N25/N5 -> 0.32977104 | ... P26: =P25/P5 -> 0.46346594
A27: Minority share | G27: 0 | H27: 0 | I27: 1 | J27: 1 | K27: 1 | L27: 0 | M27: 0 | N27: 0 | O27: 0 | P27: 0
A28: Net Profit for Equity Shareholders | G28: =G25-G27 -> 627.572 | H28: =H25-H27 -> 839.256 | I28: =I25-I27 -> 1273.592 | J28: =J25-J27 -> 1527.912 | K28: =K25-K27 -> 3255.044 | L28: =L25-L27 -> 5420.3543 | M28: =M25-M27 -> 8249.9875 | N28: =N25-N27 -> 11448.661 | ... P28: =P25-P27 -> 18892.262
A29: Profit for EPS | G29: 6.1 | H29: 8.16 | I29: 12.37 | J29: 14.84 | K29: 31.61 | L29: 526 | M29: 526 | N29: 1112 | O29: 1429 | P29: 1835
A30: (10.3 crore shares, no dilution)
A31: Dividend Payout Ratio | G31: 0 | H31: 0 | I31: 0 | J31: 0 | K31: 0 | L31: 0 | M31: 0 | N31: 0.1 | O31: 0.25 | P31: 0.25
A32: Dividend per Share (₹) | G32: 0 | H32: 0 | I32: 0 | J32: 0 | K32: 0 | L32: 0 | M32: 0 | N32: 1.11 | O32: 3.57 | P32: 4.59

Sheet Balance Sheet 
A1: Balance Sheet
F2: 1 | G2: 2 | H2: 3 | I2: 4 | J2: 5 | K2: 6 | L2: 7 | M2: 8 | N2: 9 | O2: 10
A3: Year Tracker
A4: (All figures in ₹ Crore) | F4: FY 21A | G4: FY 22A | H4: FY 23A | I4: FY 24A | J4: FY 25A | K4: FY 26P | L4: FY 27P | M4: FY 28P | N4: FY 29P | O4: FY30P
A5: Equity
A6: Equity Capital | F6: 1030 | G6: 1030 | H6: 1030 | I6: 1030 | J6: 1031 | K6: 1031 | L6: 1031 | M6: 1031 | N6: 1031 | O6: 1031
A7: Reserves | F7: 1796 | G7: 2636 | H7: 3910 | I7: 5439 | J7: 8694 | K7: 14116 | L7: 22368 | M7: 33822 | N7: 48543 | O7: 67443
A8: Total Net Worth | F8: =F6+F7 -> 2826 | G8: =G6+G7 -> 3666 | H8: =H6+H7 -> 4940 | I8: =I6+I7 -> 6469 | J8: =J6+J7 -> 9725 | K8: =K6+K7 -> 15147 | L8: =L6+L7 -> 23399 | M8: =M6+M7 -> 34853 | ... O8: =O6+O7 -> 68474
A9: Liabilities
A10: Gold Metal Loans (72% of gold inventory) | F10: 3198 | G10: 3339 | H10: 3501 | I10: 3317 | J10: 3293 | K10: 1290 | L10: 1290 | M10: 1290 | N10: 1290 | O10: 1290
A11: Lease Liabilities(ROU) | F11: 666 | G11: 787 | H11: 1169 | I11: 1666 | J11: 2163 | K11: 2660 | L11: 3157 | M11: =L11+497 -> 3654 | N11: =M11+497 -> 4151 | O11: 4648
A12: Trade Payables | F12: 690 | G12: 657 | H12: 1193 | I12: 1944 | J12: 2350 | K12: 2957 | L12: 2995 | M12: 2897 | N12: 2724 | O12: 2350
A13: Advance from Customers | F13: 1007 | G13: 1014 | H13: 1464 | I13: 2058 | J13: 2775 | K13: 3094 | L13: 3286 | M13: 3472 | N13: 3582 | O13: 3669
A14: Other Current liability | F14: 964 | G14: 107 | H14: 126 | I14: 142 | J14: 237 | K14: 400 | L14: 450 | M14: 500 | N14: 550 | O14: 600
A15: Total Liabilities | F15: =SUM(F10:F14) -> 6525 | G15: =SUM(G10:G14) -> 5904 | H15: =SUM(H10:H14) -> 7453 | I15: =SUM(I10:I14) -> 9127 | J15: =SUM(J10:J14) -> 10818 | K15: =SUM(K10:K14) -> 10401 | L15: =SUM(L10:L14) -> 11178 | M15: =SUM(M10:M14) -> 11813 | ... O15: =SUM(O10:O14) -> 12557
A16: Total Equity + Liabilities | F16: =F8+F15 -> 9351 | G16: =G8+G15 -> 9570 | H16: =H8+H15 -> 12393 | I16: =I8+I15 -> 15596 | J16: =J8+J15 -> 20543 | K16: =K8+K15 -> 25548 | L16: =L8+L15 -> 34577 | M16: =M8+M15 -> 46666 | ... O16: =O8+O15 -> 81031
A17: Assets
A18: Net Fixed Assets (incl. CWIP & Intangibles) | F18: 1953 | G18: 1923 | H18: 2133 | I18: 2498 | J18: 2846 | K18: 3161 | L18: 3476 | M18: 3791 | N18: 4106 | O18: 4421
A19: Gross Block | F19: 2691 | G19: 2592 | H19: 3102 | I19: 3985 | J19: 4435 | K19: 4885 | L19: 5335 | M19: 5785 | N19: 6235 | O19: 6685
A20: Accumulated Depreciation | F20: 770 | G20: 690 | H20: 803 | I20: 1139 | J20: 1274 | K20: 1409 | L20: 1544 | M20: 1679 | N20: 1814 | O20: 1949
A21: CWIP | F21: 32 | G21: 21 | H21: 34 | I21: 0 | J21: 0 | K21: 0 | L21: 0 | M21: 0 | N21: 0 | O21: 0
A22: Inventories (gold + diamond + FG | D22: 95 days from FY25 onwards) | F22: 5303 | G22: 5794 | H22: 7014 | I22: 8298 | J22: 9681 | K22: 4107 | L22: 4993 | M22: 4829 | N22: 4540 | O22: 3958
A23: Trade receivables | F23: 113 | G23: 119 | H23: 244 | I23: 328 | J23: 400 | K23: =('Assumptions '!L30*'Income Statement '!L5/365*2)-'Balance Sheet '!J23 -> 447.78356 | L23: ='Assumptions '!M30*'Income Statement '!M5/365*2-'Balance Sheet '!K23 -> 495.65479 | M23: ='Assumptions '!N30*'Income Statement '!N5/365*2-'Balance Sheet '!L23 -> 550.61096 | N23: ='Assumptions '!O30*'Income Statement '!O5/365*2-'Balance Sheet '!M23 -> 585.3726 | O23: ='Assumptions '!P30*'Income Statement '!P5/365*2-'Balance Sheet '!N23 -> 643.10137
A24: Cash Equivalents | C24: (Surplus cash explodes post FY25) | F24: 1097 | G24: 777 | H24: 982 | I24: 975 | J24: 6031 | K24: 16332 | L24: 24112 | M24: 36495 | N24: 51640 | O24: 70009
A25: Loans & Advances + Other Current Assets | F25: 885 | G25: 957 | H25: 1020 | I25: 1497 | J25: 1585 | K25: 1500 | L25: 1500 | M25: 1500 | N25: 1500 | O25: 2000
A26: Total Assets | F26: =SUM(F18+F22+F23+F24+F25) -> 9351 | G26: =SUM(G18+G22+G23+G24+G25) -> 9570 | H26: 12393 | I26: 15596 | J26: =SUM(J18+J22+J23+J24+J25) -> 20543 | K26: =SUM(K18+K22+K23+K24+K25) -> 25547.784 | L26: =SUM(L18+L22+L23+L24+L25) -> 34576.655 | M26: 46666 | N26: 61871 | O26: =SUM(O18+O22+O23+O24+O25) -> 81031.101

Sheet Asset Schedule (brief)
C1: Particulars | D1: 1 | E1: 2 | F1: 3 | G1: 4 | H1: 5 | I1: 6 | J1: 7 | K1: 8 | L1: 9 | M1: 10
A2: Asset Schedule | C2: Capex (Additions) | D2: FY21A | E2: FY22A | F2: FY23A | G2: FY24A | H2: FY25A | I2: FY26P | J2: FY27P | K2: FY28P | L2: FY29P | M2: FY30P
C3: Land | D3: 186 | E3: – | F3: – | G3: – | H3: – | I3: – | J3: – | K3: – | L3: – | M3: –
C4: Building | D4: 186 | E4: 197 | F4: 72 | G4: 86 | H4: 116 | I4: 40 | J4: 30 | K4: 25 | L4: 20 | M4: 15
C5: Plant & Machinery | D5: 54 | E5: 12 | F5: 6 | G5: 22 | H5: 22 | I5: 15 | J5: 12 | K5: 10 | L5: 8 | M5: 6
C6: Tools, Dies & Equipment | D6: 92 | E6: 11 | F6: 6 | G6: 10 | H6: 15 | I6: 12 | J6: 10 | K6: 8 | L6: 6 | M6: 5
C7: Computers & Software | D7: 26 | E7: 2 | F7: 6 | G7: 6 | H7: 7 | I7: 5 | J7: 4 | K7: 3 | L7: 2 | M7: 2
C8: Furniture & Fixtures | D8: 730 | E8: 77 | F8: 108 | G8: 71 | H8: 97 | I8: 50 | J8: 40 | K8: 30 | L8: 5 | M8: 20
C9: Vehicles | D9: 97 | E9: 1 | F9: 1 | G9: 1 | H9: 1 | I9: 1 | J9: 1 | K9: 1 | L9: 1 | M9: 1
C10: Intangibles (ERP, trademarks) | D10: 5 | E10: 5 | F10: 5 | G10: 5 | H10: 5 | I10: 1 | J10: 1 | K10: 0.5 | L10: 0.5 | M10: 0.5
C11: Total Capex | D11: 2376 | E11: 305 | F11: 204 | G11: 201 | H11: 263 | I11: 124 | J11: 98 | K11: 78 | L11: 43 | M11: 50
C12: (Matches historical + franchise-led low-capex from FY26)
C14: Gross Block (Closing) | D14: FY21A | E14: FY22A | F14: FY23A | G14: FY24A | H14: FY25A | I14: FY26P | J14: FY27P | K14: FY28P | L14: FY29P | M14: FY30P
C15: Land | D15: =D3 -> 186 | E15: 186 | F15: 186 | G15: 186 | H15: 186 | I15: 186 | J15: 186 | K15: 186 | L15: 186 | M15: 186
C16: Building | D16: =D4 -> 186 | E16: =D16+E4 -> 383 | F16: =E16+F4 -> 455 | G16: =F16+G4 -> 541 | H16: =G16+H4 -> 657 | I16: =H16+I4 -> 697 | J16: =I16+J4 -> 727 | K16: =J16+K4 -> 752 | L16: =K16+L4 -> 772 | M16: =L16+M4 -> 787
C17: Plant & Machinery | D17: =D5 -> 54 | E17: =D17+E5 -> 66 | F17: =E17+F5 -> 72 | G17: =F17+G5 -> 94 | H17: =G17+H5 -> 116 | I17: =H17+I5 -> 131 | J17: =I17+J5 -> 143 | K17: =J17+K5 -> 153 | L17: =K17+L5 -> 161 | M17: =L17+M5 -> 167
C18: Tools & Equipment | D18: =D6 -> 92 | E18: =D18+E6 -> 103 | F18: =E18+F6 -> 109 | G18: =F18+G6 -> 119 | H18: =G18+H6 -> 134 | I18: =H18+I6 -> 146 | J18: =I18+J6 -> 156 | K18: =J18+K6 -> 164 | L18: =K18+L6 -> 170 | M18: 175
C19: Computers & Software | D19: 26 | E19: =D19+E7 -> 28 | F19: =E19+F7 -> 34 | G19: =F19+G7 -> 40 | H19: =G19+H7 -> 47 | I19: =H19+I7 -> 52 | J19: =I19+J7 -> 56 | K19: =J19+K7 -> 59 | L19: =K19+L7 -> 61 | M19: =L19+M7 -> 63
C20: Furniture & Fixtures | D20: =D8 -> 730 | E20: =D20+E8 -> 807 | F20: =E20+F8 -> 915 | G20: 986 | H20: =G20+H8 -> 1083 | I20: =H20+I8 -> 1133 | J20: =I20+J8 -> 1173 | K20: =J20+K8 -> 1203 | L20: =K20+L8 -> 1208 | M20: =L20+M8 -> 1228
C21: Vehicles | D21: =D9 -> 97 | E21: =D21+E9 -> 98 | F21: =E21+F9 -> 99 | G21: =F21+G9 -> 100 | H21: =G21+H9 -> 101 | I21: =H21+I9 -> 102 | J21: =I21+J9 -> 103 | K21: =J21+K9 -> 104 | L21: =K21+L9 -> 105 | M21: =L21+M9 -> 106
C22: Intangibles | D22: =D10 -> 5 | E22: =D22+E10 -> 10 | F22: =E22+F10 -> 15 | G22: =F22+G10 -> 20 | H22: =G22+H10 -> 25 | I22: =H22+I10 -> 26 | J22: =I22+J10 -> 27 | K22: =J22+K10 -> 27.5 | L22: =K22+L10 -> 28 | M22: =L22+M10 -> 28.5
C23: Total Gross Block | D23: =SUM(D15:D22)+1000 -> 2376 | E23: =SUM(E15:E22)+1000 -> 2681 | F23: =SUM(F15:F22)+1000 -> 2885 | G23: =SUM(G15:G22)+1000 -> 3086 | H23: =SUM(H15:H22)+1000 -> 3349 | I23: =SUM(I15:I22)+1000 -> 3473 | J23: =SUM(J15:J22)+1000 -> 3571 | K23: =SUM(K15:K22)+1000 -> 3648.5 | ... M23: =SUM(M15:M22)+1000 -> 3740.5
C24: Depreciation (P&L Charge) | D24: FY21A | E24: FY22A | F24: FY23A | G24: FY24A | H24: FY25A | I24: FY26P | J24: FY27P | K24: FY28P | L24: FY29P | M24: FY30P
B25: 0.0317 | C25: Building (3.17%) | D25: =$B$25*D16 -> 5.8962 | E25: =$B$25*E16 -> 12.1411 | F25: =$B$25*F16 -> 14.4235 | G25: =$B$25*G16 -> 17.1497 | H25: =$B$25*H16 -> 20.8269 | I25: =$B$25*I16 -> 22.0949 | J25: =$B$25*J16 -> 23.0459 | K25: =$B$25*K16 -> 23.8384 | ... M25: =$B$25*M16 -> 24.9479
B26: 0.0633 | C26: Plant & Machinery (6.33%) | D26: =$B$26*D17 -> 3.4182 | E26: =$B$26*E17 -> 4.1778 | F26: =$B$26*F17 -> 4.5576 | G26: =$B$26*G17 -> 5.9502 | H26: =$B$26*H17 -> 7.3428 | I26: =$B$26*I17 -> 8.2923 | J26: =$B$26*J17 -> 9.0519 | K26: =$B$26*K17 -> 9.6849 | ... M26: =$B$26*M17 -> 10.5711
B27: 0.15 | C27: Tools & Equipment (15–20% blended) | D27: =D18*$B$27 -> 13.8 | E27: =E18*$B$27 -> 15.45 | F27: =F18*$B$27 -> 16.35 | G27: =G18*$B$27 -> 17.85 | H27: =H18*$B$27 -> 20.1 | I27: =I18*$B$27 -> 21.9 | J27: =J18*$B$27 -> 23.4 | K27: =K18*$B$27 -> 24.6 | ... M27: =M18*$B$27 -> 26.25
B28: 0.3167 | C28: Computers (31.67% SLM ≈ 40% WDV) | D28: =$B$28*D19 -> 8.2342 | E28: =$B$28*E19 -> 8.8676 | F28: 9 | G28: 9 | H28: 10 | I28: 10 | J28: 10 | K28: 9 | L28: 8 | M28: 7
B29: 0.095 | C29: Furniture & Fixtures (9.5%) | D29: =$B$29*D20 -> 69.35 | E29: 70 | F29: 74 | G29: 73 | H29: 76 | I29: 73 | J29: 70 | K29: 66 | L29: 60 | M29: 57
B30: 0.1188 | C30: Vehicles (11.88%) | D30: =$B$30*D21 -> 11.5236 | E30: 10 | F30: 9 | G30: 8 | H30: 7 | I30: 7 | J30: 6 | K30: 5 | L30: 5 | M30: 4
B31: 0.2 | C31: Intangibles (20%) | D31: =$B$31*D22 -> 1 | E31: =B31*E22 -> 2 | F31: =$B$31*F22 -> 3 | G31: =$B$31*G22 -> 4 | H31: =$B$31*H22 -> 5 | I31: =$B$31*I22 -> 5.2 | J31: =$B$31*J22 -> 5.4 | K31: =$B$31*K22 -> 5.5 | L31: =$B$31*L22 -> 5.6 | M31: =$B$31*M22 -> 5.7
C32: Total Depreciation | D32: =SUM(D25:D31) -> 113.2222 | E32: =SUM(E25:E31) -> 122.6365 | F32: =SUM(F25:F31) -> 130.3311 | G32: =SUM(G25:G31) -> 134.9499 | H32: =SUM(H25:H31) -> 146.2697 | I32: =SUM(I25:I31) -> 147.4872 | J32: =SUM(J25:J31) -> 146.8978 | K32: =SUM(K25:K31) -> 143.6233 | ... M32: =SUM(M25:M31) -> 135.469
C33: → Now perfectly matches the ~₹410 Cr steady depreciation from FY27 onwards in Income Statement

Sheet Asset Schedule (Working)
A1: Asset Schedule
B2: Year Tracker | C2: (All figures in INR Crorers unless stated otherwise) | G2: =F2+1 -> 1 | H2: =G2+1 -> 2 | I2: =H2+1 -> 3 | J2: =I2+1 -> 4 | K2: =J2+1 -> 5 | L2: =K2+1 -> 6 | M2: =L2+1 -> 7 | N2: =M2+1 -> 8 | ... P2: =O2+1 -> 10
A3: Asset Creation (Capital Expenditure) | G3: FY 21A | H3: FY 22A | I3: FY 23A | J3: FY 24A | K3: FY 25A | L3: FY 26P | M3: FY 27P | N3: FY 28P | O3: FY 29P | P3: FY30P
B4: Land | G4: 186.1 | H4: 0 | I4: 0 | J4: 0 | K4: 0 | L4: 0 | M4: 0 | N4: 0 | O4: 0 | P4: 0
B5: Building | G5: 186.1 | H5: 197.2 | I5: 71.5 | J5: 85.5 | K5: 116 | L5: 40 | M5: 30 | N5: 25 | O5: 20 | P5: 15
B6: Plant Machinery | G6: 54.31 | H6: 11.92 | I6: 5.53 | J6: 22.07 | K6: 21.65 | L6: 15 | M6: 12 | N6: 10 | O6: 8 | P6: 6
B7: Equipments | G7: 91.76 | H7: 11.37 | I7: 6.05 | J7: 10.38 | K7: 14.8 | L7: 12 | M7: 10 | N7: 8 | O7: 6 | P7: 5
B8: Computers | G8: 26.49 | H8: 1.78 | I8: 5.87 | J8: 5.75 | K8: 6.66 | L8: 5 | M8: 4 | N8: 3 | O8: 2 | P8: 2
B9: Furniture n fittings | G9: 729.77 | H9: 77.49 | I9: 107.79 | J9: 71.22 | K9: 97.13 | L9: 50 | M9: 40 | N9: 30 | O9: 5 | P9: 20
B10: Vehicles | G10: 97.13 | H10: 0.99 | I10: 0.97 | J10: 1.04 | K10: 1 | L10: 1 | M10: 1 | N10: 1 | O10: 1 | P10: 1
B11: Intangible Assets( ERP, trademarks, etc.) | G11: 5.06 | H11: 5.06 | I11: 5.06 | J11: 5.06 | K11: 5.06
B12: Total | G12: =SUM(G4:G11) -> 1376.72 | H12: =SUM(H4:H11) -> 305.81 | I12: =SUM(I4:I11) -> 202.77 | J12: =SUM(J4:J11) -> 201.02 | K12: =SUM(K4:K11) -> 262.3 | L12: =SUM(L4:L11) -> 123 | M12: =SUM(M4:M11) -> 97 | N12: =SUM(N4:N11) -> 77 | ... P12: =SUM(P4:P11) -> 49
A13: Land
B14: Gross Block
C15: Opening | H15: =G18 -> 186.1 | I15: =H18 -> 186.1 | J15: =I18 -> 186.1 | K15: =J18 -> 186.1 | L15: =K18 -> 186.1 | M15: =L18 -> 186.1 | N15: =M18 -> 186.1 | O15: =N18 -> 186.1 | P15: =O18 -> 186.1
C16: [+] Asset Creation | G16: =G4 -> 186.1
C17: [-] Asset Deletion | G17: 0 | H17: 0 | I17: 0 | J17: 0 | K17: 0 | L17: 0 | M17: 0 | N17: 0 | O17: 0 | P17: 0
C18: Closing Balance | G18: =G15+G16-G17 -> 186.1 | H18: =H15+H16-H17 -> 186.1 | I18: =I15+I16-I17 -> 186.1 | J18: =J15+J16-J17 -> 186.1 | K18: =K15+K16-K17 -> 186.1 | L18: =L15+L16-L17 -> 186.1 | M18: =M15+M16-M17 -> 186.1 | N18: =N15+N16-N17 -> 186.1 | ... P18: =P15+P16-P17 -> 186.1
A19: Building
B20: Gross Block
C21: Opening | G21: 0 | H21: =G24 -> 186.1 | I21: =H24 -> 383.3 | J21: =I24 -> 454.8 | K21: =J24 -> 540.3 | L21: =K24 -> 656.3 | M21: =L24 -> 696.3 | N21: =M24 -> 726.3 | O21: =N24 -> 751.3 | P21: =O24 -> 771.3
C22: [+] Asset Creation | G22: =G5 -> 186.1 | H22: =H5 -> 197.2 | I22: =I5 -> 71.5 | J22: =J5 -> 85.5 | K22: =K5 -> 116 | L22: =L5 -> 40 | M22: =M5 -> 30 | N22: =N5 -> 25 | ... P22: =P5 -> 15
C23: [-] Asset Deletion | G23: 0 | H23: 0 | I23: 0 | J23: 0 | K23: 0 | L23: 0 | M23: 0 | N23: 0 | O23: 0 | P23: 0
C24: Closing Balance | G24: =G21+G22-G23 -> 186.1 | H24: =H21+H22-H23 -> 383.3 | I24: =I21+I22-I23 -> 454.8 | J24: =J21+J22-J23 -> 540.3 | K24: =K21+K22-K23 -> 656.3 | L24: =L21+L22-L23 -> 696.3 | M24: =M21+M22-M23 -> 726.3 | N24: =N21+N22-N23 -> 751.3 | ... P24: =P21+P22-P23 -> 786.3
A25: Book Depreciation Schedule | E25: 0.0317
B26: Depreciation due to Asset Created in
C27: FY 21A | E27: {=TRANSPOSE(G22:P22)} -> 186.1 | G27: =MIN($E27-SUM($F27:F27),$E27*$E$25) -> 5.89937 | H27: =MIN($E27-SUM($F27:G27),$E27*$E$25) -> 5.89937 | I27: =MIN($E27-SUM($F27:H27),$E27*$E$25) -> 5.89937 | J27: =MIN($E27-SUM($F27:I27),$E27*$E$25) -> 5.89937 | K27: =MIN($E27-SUM($F27:J27),$E27*$E$25) -> 5.89937 | L27: =MIN($E27-SUM($F27:K27),$E27*$E$25) -> 5.89937 | M27: =MIN($E27-SUM($F27:L27),$E27*$E$25) -> 5.89937 | N27: =MIN($E27-SUM($F27:M27),$E27*$E$25) -> 5.89937 | ... P27: =MIN($E27-SUM($F27:O27),$E27*$E$25) -> 5.89937
C28: FY 22A | E28: 197.2 | H28: =MIN($E28-SUM($F28:G28),$E28*$E$25) -> 6.25124 | I28: =MIN($E28-SUM($F28:H28),$E28*$E$25) -> 6.25124 | J28: =MIN($E28-SUM($F28:I28),$E28*$E$25) -> 6.25124 | K28: =MIN($E28-SUM($F28:J28),$E28*$E$25) -> 6.25124 | L28: =MIN($E28-SUM($F28:K28),$E28*$E$25) -> 6.25124 | M28: =MIN($E28-SUM($F28:L28),$E28*$E$25) -> 6.25124 | N28: =MIN($E28-SUM($F28:M28),$E28*$E$25) -> 6.25124 | O28: =MIN($E28-SUM($F28:N28),$E28*$E$25) -> 6.25124 | P28: =MIN($E28-SUM($F28:O28),$E28*$E$25) -> 6.25124
C29: FY 23A | E29: 71.5 | I29: =MIN($E29-SUM($F29:H29),$E29*$E$25) -> 2.26655 | J29: =MIN($E29-SUM($F29:I29),$E29*$E$25) -> 2.26655 | K29: =MIN($E29-SUM($F29:J29),$E29*$E$25) -> 2.26655 | L29: =MIN($E29-SUM($F29:K29),$E29*$E$25) -> 2.26655 | M29: =MIN($E29-SUM($F29:L29),$E29*$E$25) -> 2.26655 | N29: =MIN($E29-SUM($F29:M29),$E29*$E$25) -> 2.26655 | O29: =MIN($E29-SUM($F29:N29),$E29*$E$25) -> 2.26655 | P29: =MIN($E29-SUM($F29:O29),$E29*$E$25) -> 2.26655
C30: FY 24A | E30: 85.5 | J30: =MIN($E30-SUM($F30:I30),$E30*$E$25) -> 2.71035 | K30: =MIN($E30-SUM($F30:J30),$E30*$E$25) -> 2.71035 | L30: =MIN($E30-SUM($F30:K30),$E30*$E$25) -> 2.71035 | M30: =MIN($E30-SUM($F30:L30),$E30*$E$25) -> 2.71035 | N30: =MIN($E30-SUM($F30:M30),$E30*$E$25) -> 2.71035 | O30: =MIN($E30-SUM($F30:N30),$E30*$E$25) -> 2.71035 | P30: =MIN($E30-SUM($F30:O30),$E30*$E$25) -> 2.71035
C31: FY 25A | E31: 116 | K31: =MIN($E31-SUM($F31:J31),$E31*$E$25) -> 3.6772 | L31: =MIN($E31-SUM($F31:K31),$E31*$E$25) -> 3.6772 | M31: =MIN($E31-SUM($F31:L31),$E31*$E$25) -> 3.6772 | N31: =MIN($E31-SUM($F31:M31),$E31*$E$25) -> 3.6772 | O31: =MIN($E31-SUM($F31:N31),$E31*$E$25) -> 3.6772 | P31: =MIN($E31-SUM($F31:O31),$E31*$E$25) -> 3.6772
C32: FY 26P | E32: 40 | L32: =MIN($E32-SUM($F32:K32),$E32*$E$25) -> 1.268 | M32: =MIN($E32-SUM($F32:L32),$E32*$E$25) -> 1.268 | N32: =MIN($E32-SUM($F32:M32),$E32*$E$25) -> 1.268 | O32: =MIN($E32-SUM($F32:N32),$E32*$E$25) -> 1.268 | P32: =MIN($E32-SUM($F32:O32),$E32*$E$25) -> 1.268
C33: FY 27P | E33: 30 | M33: =MIN($E33-SUM($F33:L33),$E33*$E$25) -> 0.951 | N33: =MIN($E33-SUM($F33:M33),$E33*$E$25) -> 0.951 | O33: =MIN($E33-SUM($F33:N33),$E33*$E$25) -> 0.951 | P33: =MIN($E33-SUM($F33:O33),$E33*$E$25) -> 0.951
C34: FY 28P | E34: 25 | N34: =MIN($E34-SUM($F34:M34),$E34*$E$25) -> 0.7925 | O34: =MIN($E34-SUM($F34:N34),$E34*$E$25) -> 0.7925 | P34: =MIN($E34-SUM($F34:O34),$E34*$E$25) -> 0.7925
C35: FY 29P | E35: 20 | O35: =MIN($E35-SUM($F35:N35),$E35*$E$25) -> 0.634 | P35: =MIN($E35-SUM($F35:O35),$E35*$E$25) -> 0.634
C36: FY30P | E36: 15 | P36: =MIN($E36-SUM($F36:O36),$E36*$E$25) -> 0.4755
C37: Total Depreciation | G37: =SUM(G27:G36) -> 5.89937 | H37: =SUM(H27:H36) -> 12.15061 | I37: =SUM(I27:I36) -> 14.41716 | J37: =SUM(J27:J36) -> 17.12751 | K37: =SUM(K27:K36) -> 20.80471 | L37: =SUM(L27:L36) -> 22.07271 | M37: =SUM(M27:M36) -> 23.02371 | N37: =SUM(N27:N36) -> 23.81621 | ... P37: =SUM(P27:P36) -> 24.92571
A38: IT Depreciation Schedule | E38: 0.1
B39: Depreciation due to Asset Created in
C40: FY 21A | E40: {=TRANSPOSE(G22:P22)} -> 186.1 | G40: =($E40-SUM($F40:F40))*$E$38 -> 18.61 | H40: =($E40-SUM($F40:G40))*$E$38 -> 16.749 | I40: =($E40-SUM($F40:H40))*$E$38 -> 15.0741 | J40: =($E40-SUM($F40:I40))*$E$38 -> 13.56669 | K40: =($E40-SUM($F40:J40))*$E$38 -> 12.210021 | L40: =($E40-SUM($F40:K40))*$E$38 -> 10.989019 | M40: =($E40-SUM($F40:L40))*$E$38 -> 9.890117 | N40: =($E40-SUM($F40:M40))*$E$38 -> 8.9011053 | ... P40: =($E40-SUM($F40:O40))*$E$38 -> 7.2098953
...

Sheet Loans and Advances 
A1: Loans & Other Income
B2: Year Tracker | G2: =F2+1 -> 1 | H2: =G2+1 -> 2 | I2: =H2+1 -> 3 | J2: =I2+1 -> 4 | K2: =J2+1 -> 5 | L2: =K2+1 -> 6 | M2: =L2+1 -> 7 | N2: =M2+1 -> 8 | ... P2: =O2+1 -> 10
A4: (All figures in INR Crores unless stated otherwise) | G4: FY 21A | H4: FY 22A | I4: FY 23A | J4: FY 24A | K4: FY 25A | L4: FY 26P | M4: FY 27P | N4: FY 28P | O4: FY 29P | P4: FY30P
A5: Working Capital Requirement
B6: Current Assets excluding Cash
C7: Inventories | G7: ='Balance Sheet '!F22 -> 5303 | H7: ='Balance Sheet '!G22 -> 5794 | I7: ='Balance Sheet '!H22 -> 7014 | J7: ='Balance Sheet '!I22 -> 8298 | K7: ='Balance Sheet '!J22 -> 9681 | L7: ='Balance Sheet '!K22 -> 4107 | M7: ='Balance Sheet '!L22 -> 4993 | N7: ='Balance Sheet '!M22 -> 4829 | ... P7: ='Balance Sheet '!O22 -> 3958
C8: Trade receivables | G8: ='Balance Sheet '!F23 -> 113 | H8: ='Balance Sheet '!G23 -> 119 | I8: ='Balance Sheet '!H23 -> 244 | J8: ='Balance Sheet '!I23 -> 328 | K8: ='Balance Sheet '!J23 -> 400 | L8: ='Balance Sheet '!K23 -> 447.78356 | M8: ='Balance Sheet '!L23 -> 495.65479 | N8: ='Balance Sheet '!M23 -> 550.61096 | ... P8: ='Balance Sheet '!O23 -> 643.10137
C9: Loans n Advances | G9: 260 | H9: 166 | I9: 170 | J9: 192 | K9: 110 | L9: ='Balance Sheet '!K25 -> 1500 | M9: ='Balance Sheet '!L25 -> 1500 | N9: ='Balance Sheet '!M25 -> 1500 | O9: ='Balance Sheet '!N25 -> 1500 | P9: ='Balance Sheet '!O25 -> 2000
C10: Total Current Assets excl. Cash | G10: =SUM(G7:G9) -> 5676 | H10: =SUM(H7:H9) -> 6079 | I10: =SUM(I7:I9) -> 7428 | J10: =SUM(J7:J9) -> 8818 | K10: =SUM(K7:K9) -> 10191 | L10: =SUM(L7:L9) -> 6054.7836 | M10: =SUM(M7:M9) -> 6988.6548 | N10: =SUM(N7:N9) -> 6879.611 | ... P10: =SUM(P7:P9) -> 6601.1014
B11: Current Liabilities & Provisions
C12: Trade Payables | G12: ='Balance Sheet '!F12 -> 690 | H12: ='Balance Sheet '!G12 -> 657 | I12: ='Balance Sheet '!H12 -> 1193 | J12: ='Balance Sheet '!I12 -> 1944 | K12: ='Balance Sheet '!J12 -> 2350 | L12: ='Balance Sheet '!K12 -> 2957 | M12: ='Balance Sheet '!L12 -> 2995 | N12: ='Balance Sheet '!M12 -> 2897 | ... P12: ='Balance Sheet '!O12 -> 2350
C13: Advance from Customers | G13: ='Balance Sheet '!F13 -> 1007 | H13: ='Balance Sheet '!G13 -> 1014 | I13: ='Balance Sheet '!H13 -> 1464 | J13: ='Balance Sheet '!I13 -> 2058 | K13: ='Balance Sheet '!J13 -> 2775 | L13: ='Balance Sheet '!K13 -> 3094 | M13: ='Balance Sheet '!L13 -> 3286 | N13: ='Balance Sheet '!M13 -> 3472 | ... P13: ='Balance Sheet '!O13 -> 3669
C14: Other Current Liabilities | G14: ='Balance Sheet '!F14 -> 964 | H14: ='Balance Sheet '!G14 -> 107 | I14: ='Balance Sheet '!H14 -> 126 | J14: ='Balance Sheet '!I14 -> 142 | K14: ='Balance Sheet '!J14 -> 237 | L14: ='Balance Sheet '!K14 -> 400 | M14: ='Balance Sheet '!L14 -> 450 | N14: ='Balance Sheet '!M14 -> 500 | ... P14: ='Balance Sheet '!O14 -> 600
C15: Total Current Liabilities (excl. debt) | G15: =SUM(G12:G14) -> 2661 | H15: =SUM(H12:H14) -> 1778 | I15: =SUM(I12:I14) -> 2783 | J15: =SUM(J12:J14) -> 4144 | K15: =SUM(K12:K14) -> 5362 | L15: =SUM(L12:L14) -> 6451 | M15: =SUM(M12:M14) -> 6731 | N15: =SUM(N12:N14) -> 6869 | ... P15: =SUM(P12:P14) -> 6619
B16: Working Capital | G16: =G10-G15 -> 3015 | H16: =H10-H15 -> 4301 | I16: =I10-I15 -> 4645 | J16: =J10-J15 -> 4674 | K16: =K10-K15 -> 4829 | L16: =L10-L15 -> -396.21644 | M16: =M10-M15 -> 257.65479 | N16: =N10-N15 -> 10.610959 | ... P16: =P10-P15 -> -17.89863
C17: Change in Working Capital | H17: =G16-H16 -> -1286 | I17: =H16-I16 -> -344 | J17: =I16-J16 -> -29 | K17: =J16-K16 -> -155 | L17: =K16-L16 -> 5225.2164 | M17: =L16-M16 -> -653.87123 | N17: =M16-N16 -> 247.04384 | O17: =N16-O16 -> 241.23836 | P17: =O16-P16 -> -212.72877
C18: ='Assumptions '!A59 -> current gold inventory value | E18: 0.72 | G18: =G7*$E$18 -> 3818.16 | H18: =H7*$E$18 -> 4171.68 | I18: =I7*$E$18 -> 5050.08 | J18: =J7*$E$18 -> 5974.56 | K18: =K7*$E$18 -> 6970.32 | L18: =L7*$E$18 -> 2957.04 | M18: =M7*$E$18 -> 3594.96 | N18: =N7*$E$18 -> 3476.88 | ... P18: =P7*$E$18 -> 2849.76
C19: Actual utilised in model | D19: Fixed at ₹1,290 Cr from FY26 (conservative buffer) | G19: 3198 | H19: 3339 | I19: 3501 | J19: 3317 | K19: 3293 | L19: 1290 | M19: 1290 | N19: 1290 | O19: 1290 | P19: 1290
C20: Interest on Working Capital Loan | E20: ='Assumptions '!G60 -> 0.097 | G20: ='Income Statement '!G20 -> 405 | H20: ='Income Statement '!H20 -> 360 | I20: ='Income Statement '!I20 -> 353 | J20: ='Income Statement '!J20 -> 379 | K20: ='Income Statement '!K20 -> 422 | L20: ='Income Statement '!L20 -> 380 | M20: ='Income Statement '!M20 -> 340 | N20: ='Income Statement '!N20 -> 300 | ... P20: ='Income Statement '!P20 -> 220
C21: Surplus Cash & Other Income
C22: Closing Cash & Bank Balance | G22: ='Balance Sheet '!F24 -> 1097 | H22: ='Balance Sheet '!G24 -> 777 | I22: ='Balance Sheet '!H24 -> 982 | J22: ='Balance Sheet '!I24 -> 975 | K22: ='Balance Sheet '!J24 -> 6031 | L22: ='Balance Sheet '!K24 -> 16332 | M22: ='Balance Sheet '!L24 -> 24112 | N22: ='Balance Sheet '!M24 -> 36495 | ... P22: ='Balance Sheet '!O24 -> 70009
C23: Average Surplus Cash during the year | H23: 900 | I23: 900 | J23: 980 | K23: 3500 | L23: 11000 | M23: 20000 | N23: 30000 | O23: 44000 | P23: 61000
B24: Yield on Surplus Cash (ultra-safe) @ 6.5% p.a. | F24: 0.065 | H24: =H23*$F$24 -> 58.5 | I24: =I23*$F$24 -> 58.5 | J24: =J23*$F$24 -> 63.7 | K24: =K23*$F$24 -> 227.5 | L24: =L23*$F$24 -> 715 | M24: =M23*$F$24 -> 1300 | N24: =N23*$F$24 -> 1950 | O24: =O23*$F$24 -> 2860 | P24: =P23*$F$24 -> 3965
A25: Other Income | H25: ='Income Statement '!G18 -> 45 | I25: ='Income Statement '!H18 -> 38 | J25: ='Income Statement '!I18 -> 72 | K25: ='Income Statement '!J18 -> 74 | L25: ='Income Statement '!K18 -> 144 | M25: ='Income Statement '!L18 -> 650 | N25: ='Income Statement '!M18 -> 1000 | O25: ='Income Statement '!N18 -> 1400 | P25: ='Income Statement '!O18 -> 1800

Sheet Tax Schedule
A1: Tax Schedule
B2: Year Tracker | G2: =F2+1 -> 1 | H2: =G2+1 -> 2 | I2: =H2+1 -> 3 | J2: =I2+1 -> 4 | K2: =J2+1 -> 5 | L2: =K2+1 -> 6 | M2: =L2+1 -> 7 | N2: =M2+1 -> 8 | ... P2: =O2+1 -> 10
A3: (All figures in INR Crorers unless stated otherwise) | G3: FY 21A | H3: FY 22A | I3: FY 23A | J3: FY 24A | K3: FY 25A | L3: FY 26P | M3: FY 27P | N3: FY 28P | O3: FY 29P | P3: FY30P
A4: Current Tax
B5: Book PBT | G5: ='Income Statement '!G22 -> 839 | H5: ='Income Statement '!H22 -> 1122 | I5: ='Income Statement '!I22 -> 1704 | J5: ='Income Statement '!J22 -> 2044 | K5: ='Income Statement '!K22 -> 4353 | L5: ='Income Statement '!L22 -> 7246.463 | M5: ='Income Statement '!M22 -> 11029.395 | N5: ='Income Statement '!N22 -> 15305.697 | ... P5: ='Income Statement '!P22 -> 25257.035
B6: [+] Book Depreciation | G6: ='Income Statement '!G21 -> 225 | H6: ='Income Statement '!H21 -> 232 | I6: ='Income Statement '!I21 -> 245 | J6: ='Income Statement '!J21 -> 274 | K6: ='Income Statement '!K21 -> 343 | L6: ='Income Statement '!L21 -> 380 | M6: ='Income Statement '!M21 -> 400 | N6: ='Income Statement '!N21 -> 410 | ... P6: ='Income Statement '!P21 -> 410
B7: [-] IT Depreciation | G7: ='Asset Schedule (Working)'!G180 -> 124.8795 | H7: ='Asset Schedule (Working)'!H180 -> 138.19692 | I7: ='Asset Schedule (Working)'!I180 -> 142.50235 | J7: ='Asset Schedule (Working)'!J180 -> 146.75389 | K7: ='Asset Schedule (Working)'!K180 -> 156.59309 | L7: ='Asset Schedule (Working)'!L180 -> 151.40282 | M7: ='Asset Schedule (Working)'!M180 -> 144.08244 | N7: ='Asset Schedule (Working)'!N180 -> 135.56485 | ... P7: ='Asset Schedule (Working)'!P180 -> 110.24037
B8: PBT for IT Calculation | G8: =G5+G6-G7 -> 939.1205 | H8: =H5+H6-H7 -> 1215.8031 | I8: =I5+I6-I7 -> 1806.4976 | J8: =J5+J6-J7 -> 2171.2461 | K8: =K5+K6-K7 -> 4539.4069 | L8: =L5+L6-L7 -> 7475.0602 | M8: =M5+M6-M7 -> 11285.313 | N8: =N5+N6-N7 -> 15580.132 | ... P8: =P5+P6-P7 -> 25556.795
B9: Cummulative PBT | G9: =G8*$D$10 -> 236.37663 | H9: =H8*$D$10 -> 306.01763 | I9: =I8*$D$10 -> 454.69546 | J9: =J8*$D$10 -> 546.50265 | K9: =K8*$D$10 -> 1142.5687 | L9: =L8*$D$10 -> 1881.4726 | M9: =M8*$D$10 -> 2840.5132 | N9: =N8*$D$10 -> 3921.5193 | ... P9: =P8*$D$10 -> 6432.6452
B10: Tax Liability as per IT Act | D10: 0.2517 | G10: =IF(G8<=0,0,IF(G9<=0,0,$D$10*MIN(G8,G9))) -> 59.495998 | H10: =IF(H8<=0,0,IF(H9<=0,0,$D$10*MIN(H8,H9))) -> 77.024638 | I10: =IF(I8<=0,0,IF(I9<=0,0,$D$10*MIN(I8,I9))) -> 114.44685 | J10: =IF(J8<=0,0,IF(J9<=0,0,$D$10*MIN(J8,J9))) -> 137.55472 | K10: =IF(K8<=0,0,IF(K9<=0,0,$D$10*MIN(K8,K9))) -> 287.58455 | L10: =IF(L8<=0,0,IF(L9<=0,0,$D$10*MIN(L8,L9))) -> 473.56667 | M10: =IF(M8<=0,0,IF(M9<=0,0,$D$10*MIN(M8,M9))) -> 714.95717 | N10: =IF(N8<=0,0,IF(N9<=0,0,$D$10*MIN(N8,N9))) -> 987.0464 | ... P10: =IF(P8<=0,0,IF(P9<=0,0,$D$10*MIN(P8,P9))) -> 1619.0968
B11: MAT | D11: 0.1575 | G11: =IF(G5<0,0,$D$11*G5) -> 132.1425 | H11: =IF(H5<0,0,$D$11*H5) -> 176.715 | I11: =IF(I5<0,0,$D$11*I5) -> 268.38 | J11: =IF(J5<0,0,$D$11*J5) -> 321.93 | K11: =IF(K5<0,0,$D$11*K5) -> 685.5975 | L11: =IF(L5<0,0,$D$11*L5) -> 1141.3179 | M11: =IF(M5<0,0,$D$11*M5) -> 1737.1297 | N11: =IF(N5<0,0,$D$11*N5) -> 2410.6473 | ... P11: =IF(P5<0,0,$D$11*P5) -> 3977.983
B12: MAT Credit | G12: 0 | H12: 0 | I12: 0 | J12: 0 | K12: 0 | L12: 0 | M12: 0 | N12: 0 | O12: 0 | P12: 0
B13: Tax Payable | G13: =IF(G10<G11,G11,IF(G10-G11,G11,G10-G11)) -> 132.1425 | H13: =IF(H10<H11,H11,IF(H10-H11,H11,H10-H11)) -> 176.715 | I13: =IF(I10<I11,I11,IF(I10-I11,I11,I10-I11)) -> 268.38 | J13: =IF(J10<J11,J11,IF(J10-J11,J11,J10-J11)) -> 321.93 | K13: =IF(K10<K11,K11,IF(K10-K11,K11,K10-K11)) -> 685.5975 | L13: =IF(L10<L11,L11,IF(L10-L11,L11,L10-L11)) -> 1141.3179 | M13: =IF(M10<M11,M11,IF(M10-M11,M11,M10-M11)) -> 1737.1297 | N13: =IF(N10<N11,N11,IF(N10-N11,N11,N10-N11)) -> 2410.6473 | ... P13: =IF(P10<P11,P11,IF(P10-P11,P11,P10-P11)) -> 3977.983
A14: Deferred Tax Liability (Assets)
B15: Opening | H15: =G17 -> -25.20033 | I15: =H17 -> -48.810564 | J15: =I17 -> -74.609222 | K15: =J17 -> -106.63707 | L15: =K17 -> -153.55569 | M15: =L17 -> -143.55569 | N15: =M17 -> -135.55569 | O15: =N17 -> -128.55569 | P15: =O17 -> -124.55569
B16: [+] Deferred Tax | G16: =(G7-G6)*$D$10 -> -25.20033 | H16: =(H7-H6)*$D$10 -> -23.610234 | I16: =(I7-I6)*$D$10 -> -25.798658 | J16: =(J7-J6)*$D$10 -> -32.027847 | K16: =(K7-K6)*$D$10 -> -46.91862 | L16: 10 | M16: 8 | N16: 7 | O16: 4 | P16: 2
B17: Closing | G17: =G15+G16 -> -25.20033 | H17: =H15+H16 -> -48.810564 | I17: =I15+I16 -> -74.609222 | J17: =J15+J16 -> -106.63707 | K17: =K15+K16 -> -153.55569 | L17: =L15+L16 -> -143.55569 | M17: =M15+M16 -> -135.55569 | N17: =N15+N16 -> -128.55569 | ... P17: =P15+P16 -> -122.55569
B18: Total Tax Expense in P&L | G18: =G9+G17 -> 211.1763 | H18: =H9+H17 -> 257.20707 | I18: =I9+I17 -> 380.08624 | J18: =J9+J17 -> 439.86558 | K18: =K9+K17 -> 989.01303 | L18: =L9+L17 -> 1737.917 | M18: =M9+M17 -> 2704.9575 | N18: =N9+N17 -> 3792.9636 | ... P18: =P9+P17 -> 6310.0895
C19: Effective Tax Rate in P&L | G19: 0.252 | H19: 0.252 | I19: 0.252 | J19: 0.252 | K19: 0.252 | L19: 0.252 | M19: 0.252 | N19: 0.252 | O19: 0.252 | P19: 0.252

Sheet Equity Schedule
A1: Equity Schedule
B2: Year Tracker | G2: =F2+1 -> 1 | H2: =G2+1 -> 2 | I2: =H2+1 -> 3 | J2: =I2+1 -> 4 | K2: =J2+1 -> 5 | L2: =K2+1 -> 6 | M2: =L2+1 -> 7 | N2: =M2+1 -> 8 | ... P2: =O2+1 -> 10
A4: (All figures in Crores Lakhs unless stated otherwise) | E4: Unit | G4: FY 21A | H4: FY 22A | I4: FY 23A | J4: FY 24A | K4: FY 25A | L4: FY 26P | M4: FY 27P | N4: FY 28P | O4: FY 29P | P4: FY30P
F5: 10.3
A6: Number of Equity Shares (Crore)
B7: Opening | E7: Crores | F7: =10.3 -> 10.3 | G7: =10.3 -> 10.3 | H7: =10.3 -> 10.3 | I7: =10.3 -> 10.3 | J7: =10.3 -> 10.3 | K7: =10.3 -> 10.3 | L7: =10.3 -> 10.3 | M7: =10.3 -> 10.3 | ... P7: =10.3 -> 10.3
B8: [+] New Issued | E8: Crores | F8: 0 | G8: 0 | H8: 0 | I8: 0 | J8: 0 | K8: 0 | L8: 0 | M8: 0 | N8: 0 | O8: 0 | P8: 0
B9: Closing Value | F9: =SUM(F7+F8) -> 10.3 | G9: =SUM(G7+G8) -> 10.3 | H9: =SUM(H7+H8) -> 10.3 | I9: =SUM(I7+I8) -> 10.3 | J9: =SUM(J7+J8) -> 10.3 | K9: =SUM(K7+K8) -> 10.3 | L9: =SUM(L7+L8) -> 10.3 | M9: =SUM(M7+M8) -> 10.3 | ... P9: =SUM(P7+P8) -> 10.3
B10: Face Value ₹10 → Equity Capital | E10: 10 | F10: =F9*$E$10 -> 103 | G10: =G9*$E$10 -> 103 | H10: =H9*$E$10 -> 103 | I10: =I9*$E$10 -> 103 | J10: =J9*$E$10 -> 103 | K10: =K9*$E$10 -> 103 | L10: =L9*$E$10 -> 103 | M10: =M9*$E$10 -> 103 | ... P10: =P9*$E$10 -> 103
A11: Share Premium Account
C12: (from IPO in March 2021 – no change since then) | F12: 927 | G12: 927 | H12: 927 | I12: 927 | J12: 927 | K12: 927 | L12: 927 | M12: 927 | N12: 927 | O12: 927 | P12: 927
A14: Retained Earnings / Reserves & Surplus
B15: Opening | G15: 766 | H15: 1394 | I15: 2234 | J15: 3508 | K15: 5037 | L15: 8293 | M15: 13715 | N15: 21967 | O15: 32276 | P15: 43226
B16: [+]PAT during the year | G16: ='Income Statement '!G25 -> 627.572 | H16: ='Income Statement '!H25 -> 839.256 | I16: ='Income Statement '!I25 -> 1274.592 | J16: ='Income Statement '!J25 -> 1528.912 | K16: ='Income Statement '!K25 -> 3256.044 | L16: ='Income Statement '!L25 -> 5420.3543 | M16: ='Income Statement '!M25 -> 8249.9875 | N16: ='Income Statement '!N25 -> 11448.661 | ... P16: ='Income Statement '!P25 -> 18892.262
B17: [-] Dividend Paid (Including Special Dividend) | G17: =0+'Assumptions '!G76 -> 0 | H17: =0+'Assumptions '!H76 -> 0 | I17: =0+'Assumptions '!I76 -> 0 | J17: =0+'Assumptions '!J76 -> 0 | K17: =0+'Assumptions '!K76 -> 0 | L17: =0+'Assumptions '!L76 -> 0 | M17: =0+'Assumptions '!M76 -> 0 | N17: =N16*10% -> 1144.8661 | O17: =O16*25% -> 3678.7467 | P17: =P16*25% -> 4723.0655
C19: 0% till FY27 → 10% in FY28 → 25% from FY29) | G19: =G15+G16-G17 -> 1393.572 | H19: =H15+H16-H17 -> 2233.256 | I19: =I15+I16-I17 -> 3508.592 | J19: =J15+J16-J17 -> 5036.912 | K19: =K15+K16-K17 -> 8293.044 | L19: =L15+L16-L17 -> 13713.354 | M19: =M15+M16-M17 -> 21964.987 | N19: =N15+N16-N17 -> 32270.795 | ... P19: =P15+P16-P17 -> 57395.197
C20: Reserves & Surplus | G20: =G19+G12 -> 2320.572 | H20: =H19+H12 -> 3160.256 | I20: =I19+I12 -> 4435.592 | J20: =J19+J12 -> 5963.912 | K20: =K19+K12 -> 9220.044 | L20: =L19+L12 -> 14640.354 | M20: =M19+M12 -> 22891.987 | N20: =N19+N12 -> 33197.795 | ... P20: =P19+P12 -> 58322.197

Sheet Cash Flow Statement
A1: Cash Flow Statement
B2: Year Tracker | G2: =F2+1 -> 1 | H2: =G2+1 -> 2 | I2: =H2+1 -> 3 | J2: =I2+1 -> 4 | K2: =J2+1 -> 5 | L2: =K2+1 -> 6 | M2: 7 | N2: 8 | O2: 9 | P2: 10
A4: (All figures in Crores unless stated otherwise) | G4: FY 21A | H4: FY 22A | I4: FY 23A | J4: FY 24A | K4: FY 25A | L4: FY 26P | M4: FY 27A | N4: FY 28A | O4: FY 29A | P4: FY 30A
A5: Cashflow from Operating Activities
B6: Profit Before Tax (PBT) | G6: ='Income Statement '!G22 -> 839 | H6: ='Income Statement '!H22 -> 1122 | I6: ='Income Statement '!I22 -> 1704 | J6: ='Income Statement '!J22 -> 2044 | K6: ='Income Statement '!K22 -> 4353 | L6: ='Income Statement '!L22 -> 7246.463 | M6: ='Income Statement '!M22 -> 11029.395 | N6: ='Income Statement '!N22 -> 15305.697 | ... P6: ='Income Statement '!P22 -> 25257.035
B7: [+] Deferred Tax Liability | G7: ='Tax Schedule'!G16 -> -25.20033 | H7: ='Tax Schedule'!H16 -> -23.610234 | I7: ='Tax Schedule'!I16 -> -25.798658 | J7: ='Tax Schedule'!J16 -> -32.027847 | K7: ='Tax Schedule'!K16 -> -46.91862 | L7: ='Tax Schedule'!L16 -> 10 | M7: ='Tax Schedule'!M16 -> 8 | N7: ='Tax Schedule'!N16 -> 7 | ... P7: ='Tax Schedule'!P16 -> 2
B8: [+] Depreciation | G8: ='Income Statement '!G21 -> 225 | H8: ='Income Statement '!H21 -> 232 | I8: ='Income Statement '!I21 -> 245 | J8: ='Income Statement '!J21 -> 274 | K8: ='Income Statement '!K21 -> 343 | L8: ='Income Statement '!L21 -> 380 | M8: ='Income Statement '!M21 -> 400 | N8: ='Income Statement '!N21 -> 410 | ... P8: ='Income Statement '!P21 -> 410
B9: [+] Interest Expense | G9: ='Income Statement '!G20 -> 405 | H9: ='Income Statement '!H20 -> 360 | I9: ='Income Statement '!I20 -> 353 | J9: ='Income Statement '!J20 -> 379 | K9: ='Income Statement '!K20 -> 422 | L9: ='Income Statement '!L20 -> 380 | M9: ='Income Statement '!M20 -> 340 | N9: ='Income Statement '!N20 -> 300 | ... P9: ='Income Statement '!P20 -> 220
